Workbook

Sheet 7" Liner Tally NFQ17-8A
K1: AS RUN TALLY
E2: BAKER HUGHES 7" LINER TALLY
D5: Tension: | E5: 929 | G5: Well: | H5: NFQ17-8A | K5: Date: | M5: 45559
D6: Burst: | E6: 11540 Psi | G6: Rig: | H6: West Tucana | K6: Qatar Gas Reps: | M6: Scott Jones / Stephen Bungay
D7: Collapse: | E7: 8530 Psi | G7: Liner Run #: | H7: 1 | K7: Baker Hughes Reps: | M7: Seshu Chapala / Arthur Jones Johnston
D8: Casing Size: | E8: 7 | G8: Block Weight: | H8: 95 | K8: 9-5/8" Shoe: | M8: 13182.61
D9: Weight: | E9: 29 | G9: Drift: | H9: 6.059 in | K9: Shoe Depth: | M9: =M10-5 -> 21381 | N9: 49.47
D10: Connection Type 1: | E10: TSH Wedge 563® | G10: Connection Type 2: | H10: TSH Wedge 563® | K10: Total Depth: | M10: 21386 | N10: 27.58
D11: Grade: | E11: SANICRO 28-110 | G11: Grade: | H11: SANICRO 28-110 | K11: Rat Hole: | M11: =M10-M9 -> 5 | O11: distance from ccl to bottom | R11: =R12+R13 -> 18.92
D12: Make Up Loss: | E12: 4.05 | G12: Make Up Loss: | H12: 4.05 | K12: Top of 7" Liner: | M12: =J329 -> 12116.38 | O12: distance from ccl to mid element | R12: 16.2
D13: Casing Avg Calipered ID: | E13: 6.220 in | G13: Csg Nom ID: | H13: 6.184 | K13: Top of Whipstock Window: | M13: 12418.71 | N13: Pump Output | O13: distance from bottom to mid element | R13: 2.72
D14: Mud Weight: | E14: 11.8 | G14: Centralizers Type: | H14: Red - X Bow Spring | K14: 10-3/4" X-Over: | M14: 1277.56 | N14: 0.12
D15: BF: | E15: =(65.45-E14)/65.45 -> 0.8197097 | G15: Total Centralizers: | H15: =SUM(C18:C277,C278:C283) -> 500
A16: RUN | B16: DESCRIPTION | C16: CENTRALIZERS | E16: DECK | F16: JOINT | G16: EFFECTIVE | H16: JOINT | I16: TOTAL | J16: DEPTH OF | K16: EST STRG | L16: top of jt seen at CT depth (ft) | M16: top of jt seen at (ft) | O16: Calc CCL depth | P16: CCL diff | Q16: final run | R16: expected top joint ( CT depth)
A17: NUM. | C17: No. | D17: Type | E17: NUM. | F17: LENGTH | G17: LENGTH | H17: IN/OUT | I17: LENGTH | J17: TOP OF JT | K17: WEIGHT | M17: COMMENTS
A18: FLOAT SHOE ASSY QELNG-7in-FS-136-NFE | C18: - | D18: Float Shoe - Double Valve, Eccentric | F18: ='DECK TALLY'!O6 -> 3.39 | G18: =F18 -> 3.39 | H18: IN | I18: =G18 -> 3.39 | J18: =M9-G18 -> 21377.61 | K18: =$H$8+(I18*$E$9*$E$15/1000) -> 95.080586 | M18: PN: H100950451GRG1, SN: 110774-110778-1, Max OD: 7.661", 29#, L80
C19: 2 | D19: Shoe Jt - TSH Wedge 563 | F19: ='DECK TALLY'!O7 -> 36.86 | G19: =F19 -> 36.86 | H19: IN | I19: =IF(H19="IN",I18+G19,I18) -> 40.25 | J19: =IF(I19="","",$M$9-I19) -> 21340.75 | K19: =$H$8+(I19*$E$9*$E$15/1000) -> 95.956806
A20: FLOAT COLLAR ASSY QELNG-7in-FC-136-NFE | C20: 1 | D20: Bttm Pup Jt. - TSH Wedge 563 | F20: ='DECK TALLY'!O9 -> 18.51 | G20: =F20-($H$12/12) -> 18.1725 | H20: IN | I20: =IF(H20="IN",I19+G20,I19) -> 58.4225 | J20: =IF(I20="","",$M$9-I20) -> 21322.577 | K20: =$H$8+(I20*$E$9*$E$15/1000) -> 96.388795 | M20: PN: H101890295GRG1, SN: 110696-110679-1, Max OD: 7.671", 29#, L80
C21: - | D21: Float Collar - Double Valve | F21: ='DECK TALLY'!O10 -> 2.91 | G21: =F21 -> 2.91 | H21: IN | I21: =IF(H21="IN",I20+G21,I20) -> 61.3325 | J21: =IF(I21="","",$M$9-I21) -> 21319.667 | K21: =$H$8+(I21*$E$9*$E$15/1000) -> 96.457971
C22: 1 | D22: Top Pup Jt. - TSH Wedge 563 | F22: ='DECK TALLY'!O11 -> 17.53 | G22: =F22 -> 17.53 | H22: IN | I22: =IF(H22="IN",I21+G22,I21) -> 78.8625 | J22: =IF(I22="","",$M$9-I22) -> 21302.138 | K22: =$H$8+(I22*$E$9*$E$15/1000) -> 96.874686
A23: LANDING COLLAR ASSY QELNG-7in-LC-156-NFE | C23: 1 | D23: Bttm Pup Jt. - TSH Wedge 563 | F23: ='DECK TALLY'!O13 -> 18.18 | G23: =F23-($H$12/12) -> 17.8425 | H23: IN | I23: =IF(H23="IN",I22+G23,I22) -> 96.705 | J23: =IF(I23="","",$M$9-I23) -> 21284.295 | K23: =$H$8+(I23*$E$9*$E$15/1000) -> 97.298831 | M23: LFC Landing Collar (Ball Seat Sheared): PN: H274120450GRG1, SN: 108421653-01, Max OD: 7.654"
C24: - | D24: LFC Landing Collar | F24: ='DECK TALLY'!O14 -> 5.16 | G24: =F24 -> 5.16 | H24: IN | I24: =IF(H24="IN",I23+G24,I23) -> 101.865 | J24: =IF(I24="","",$M$9-I24) -> 21279.135 | K24: =$H$8+(I24*$E$9*$E$15/1000) -> 97.421492
C25: 1 | D25: Top Pup Jt. - TSH Wedge 563 | F25: ='DECK TALLY'!O15 -> 18.59 | G25: =F25 -> 18.59 | H25: IN | I25: =IF(H25="IN",I24+G25,I24) -> 120.455 | J25: =IF(I25="","",$M$9-I25) -> 21260.545 | K25: =$H$8+(I25*$E$9*$E$15/1000) -> 97.863406
G26: =F26 -> 0 | H26: OUT | I26: =IF(H26="IN",I25+G26,I25) -> 120.455 | J26: =IF(I26="","",$M$9-I26) -> 21260.545 | K26: =$H$8+(I26*$E$9*$E$15/1000) -> 97.863406
A27: 1 | B27: TSH WEGDE 563 | C27: 2 | D27: Bow Spring | E27: ='DECK TALLY'!B6 -> A1 | F27: ='DECK TALLY'!C6 -> 36.57 | G27: =F27-($E$12/12) -> 36.2325 | H27: IN | I27: =IF(H27="IN",I26+G27,I26) -> 156.6875 | J27: =IF(I27="","",$M$9-I27) -> 21224.312 | K27: =$H$8+(I27*$E$9*$E$15/1000) -> 98.72471 | M27: NO BAKER LOCK APPLIED ON ST
A28: =A27+1 -> 2 | B28: TSH WEGDE 563 | C28: 2 | D28: Bow Spring | E28: ='DECK TALLY'!B7 -> A2 | F28: ='DECK TALLY'!C7 -> 37.23 | G28: =F28-($E$12/12) -> 36.8925 | H28: IN | I28: =IF(H28="IN",I27+G28,I27) -> 193.58 | J28: =IF(I28="","",$M$9-I28) -> 21187.42 | K28: =$H$8+(I28*$E$9*$E$15/1000) -> 99.601703
A29: =A28+1 -> 3 | B29: TSH WEGDE 563 | C29: 2 | D29: Bow Spring | E29: ='DECK TALLY'!B8 -> A3 | F29: ='DECK TALLY'!C8 -> 37 | G29: =F29-($E$12/12) -> 36.6625 | H29: IN | I29: =IF(H29="IN",I28+G29,I28) -> 230.2425 | J29: =IF(I29="","",$M$9-I29) -> 21150.757 | K29: =$H$8+(I29*$E$9*$E$15/1000) -> 100.47323 | R29: =J29+89 -> 21239.757
A30: PJ | B30: TSH W563 PUP JNT | C30: 1 | D30: Bow Spring | E30: Pup VP-8 | F30: 18.25 | G30: =F30-($E$12/12) -> 17.9125 | H30: IN | I30: =IF(H30="IN",I29+G30,I29) -> 248.155 | J30: =IF(I30="","",$M$9-I30) -> 21132.845 | K30: =$H$8+(I30*$E$9*$E$15/1000) -> 100.89904 | M30: PLANNED PIPTAG @ | N30: 21136 | R30: =J30+89 -> 21221.845
A31: =A29+1 -> 4 | B31: TSH WEGDE 563 | C31: 2 | D31: Bow Spring | E31: ='DECK TALLY'!B9 -> A4 | F31: ='DECK TALLY'!C9 -> 36.16 | G31: =F31-($E$12/12) -> 35.8225 | H31: IN | I31: =IF(H31="IN",I30+G31,I30) -> 283.9775 | J31: =IF(I31="","",$M$9-I31) -> 21097.022 | K31: =$H$8+(I31*$E$9*$E$15/1000) -> 101.75059 | M31: PIP TAG # 1 ON JT # | N31: =E31 -> A4 | R31: =J31+89 -> 21186.022
A32: =A31+1 -> 5 | B32: TSH WEGDE 563 | C32: 1 | D32: Bow Spring | E32: ='DECK TALLY'!B10 -> A5 | F32: ='DECK TALLY'!C10 -> 36.91 | G32: =F32-($E$12/12) -> 36.5725 | H32: IN | I32: =IF(H32="IN",I31+G32,I31) -> 320.55 | J32: =IF(I32="","",$M$9-I32) -> 21060.45 | K32: =$H$8+(I32*$E$9*$E$15/1000) -> 102.61998 | M32: INSTALL EXTRA STOP COLLAR W/PIP TAG, 5 ft FROM PIN END ON JT # A4 | R32: =J32+89 -> 21149.45
A33: =A32+1 -> 6 | B33: TSH WEGDE 563 | C33: 2 | D33: Bow Spring | E33: ='DECK TALLY'!B11 -> A6 | F33: ='DECK TALLY'!C11 -> 35.36 | G33: =F33-($E$12/12) -> 35.0225 | H33: IN | I33: =IF(H33="IN",I32+G33,I32) -> 355.5725 | J33: =IF(I33="","",$M$9-I33) -> 21025.428 | K33: =$H$8+(I33*$E$9*$E$15/1000) -> 103.45252 | R33: =J33+89 -> 21114.428
A34: =A33+1 -> 7 | B34: TSH WEGDE 563 | C34: 2 | D34: Bow Spring | E34: ='DECK TALLY'!B12 -> A7 | F34: ='DECK TALLY'!C12 -> 36.41 | G34: =F34-($E$12/12) -> 36.0725 | H34: IN | I34: =IF(H34="IN",I33+G34,I33) -> 391.645 | J34: =IF(I34="","",$M$9-I34) -> 20989.355 | K34: =$H$8+(I34*$E$9*$E$15/1000) -> 104.31002 | M34: Cont. EZSV correlation | R34: =J34+89 -> 21078.355
A35: =A34+1 -> 8 | B35: TSH WEGDE 563 | C35: 2 | D35: Bow Spring | E35: ='DECK TALLY'!B13 -> A8 | F35: ='DECK TALLY'!C13 -> 36.6 | G35: =F35-($E$12/12) -> 36.2625 | H35: IN | I35: =IF(H35="IN",I34+G35,I34) -> 427.9075 | J35: =IF(I35="","",$M$9-I35) -> 20953.092 | K35: =$H$8+(I35*$E$9*$E$15/1000) -> 105.17204 | M35: ACTUAL PIP TAG DEPTH @ | N35: =J30-5 -> 21127.845 | R35: =J35+89 -> 21042.092
A36: =A35+1 -> 9 | B36: TSH WEGDE 563 | C36: 2 | D36: Bow Spring | E36: ='DECK TALLY'!B14 -> A9 | F36: ='DECK TALLY'!C14 -> 36.48 | G36: =F36-($E$12/12) -> 36.1425 | H36: IN | I36: =IF(H36="IN",I35+G36,I35) -> 464.05 | J36: =IF(I36="","",$M$9-I36) -> 20916.95 | K36: =$H$8+(I36*$E$9*$E$15/1000) -> 106.0312 | R36: =J36+89 -> 21005.95
A37: =A36+1 -> 10 | B37: TSH WEGDE 563 | C37: 2 | D37: Bow Spring | E37: ='DECK TALLY'!B15 -> B1 | F37: ='DECK TALLY'!C15 -> 36.37 | G37: =F37-($E$12/12) -> 36.0325 | H37: IN | I37: =IF(H37="IN",I36+G37,I36) -> 500.0825 | J37: =IF(I37="","",$M$9-I37) -> 20880.917 | K37: =$H$8+(I37*$E$9*$E$15/1000) -> 106.88775 | R37: =J37+89 -> 20969.917
A38: =A37+1 -> 11 | B38: TSH WEGDE 563 | C38: 2 | D38: Bow Spring | E38: ='DECK TALLY'!B16 -> B2 | F38: ='DECK TALLY'!C16 -> 36.15 | G38: =F38-($E$12/12) -> 35.8125 | H38: IN | I38: =IF(H38="IN",I37+G38,I37) -> 535.895 | J38: =IF(I38="","",$M$9-I38) -> 20845.105 | K38: =$H$8+(I38*$E$9*$E$15/1000) -> 107.73907 | R38: =J38+89 -> 20934.105
A39: =A38+1 -> 12 | B39: TSH WEGDE 563 | C39: 2 | D39: Bow Spring | E39: ='DECK TALLY'!B17 -> B3 | F39: ='DECK TALLY'!C17 -> 34.87 | G39: =F39-($E$12/12) -> 34.5325 | H39: IN | I39: =IF(H39="IN",I38+G39,I38) -> 570.4275 | J39: =IF(I39="","",$M$9-I39) -> 20810.572 | K39: =$H$8+(I39*$E$9*$E$15/1000) -> 108.55996 | R39: =J39+89 -> 20899.572
A40: =A39+1 -> 13 | B40: TSH WEGDE 563 | C40: 2 | D40: Bow Spring | E40: ='DECK TALLY'!B18 -> B4 | F40: ='DECK TALLY'!C18 -> 36.68 | G40: =F40-($E$12/12) -> 36.3425 | H40: IN | I40: =IF(H40="IN",I39+G40,I39) -> 606.77 | J40: =IF(I40="","",$M$9-I40) -> 20774.23 | K40: =$H$8+(I40*$E$9*$E$15/1000) -> 109.42388 | R40: =J40+89 -> 20863.23
A41: =A40+1 -> 14 | B41: TSH WEGDE 563 | C41: 2 | D41: Bow Spring | E41: ='DECK TALLY'!B19 -> B5 | F41: ='DECK TALLY'!C19 -> 36.66 | G41: =F41-($E$12/12) -> 36.3225 | H41: IN | I41: =IF(H41="IN",I40+G41,I40) -> 643.0925 | J41: =IF(I41="","",$M$9-I41) -> 20737.908 | K41: =$H$8+(I41*$E$9*$E$15/1000) -> 110.28733 | R41: =J41+89 -> 20826.908
A42: =A41+1 -> 15 | B42: TSH WEGDE 563 | C42: 2 | D42: Bow Spring | E42: ='DECK TALLY'!B20 -> B6 | F42: ='DECK TALLY'!C20 -> 36.05 | G42: =F42-($E$12/12) -> 35.7125 | H42: IN | I42: =IF(H42="IN",I41+G42,I41) -> 678.805 | J42: =IF(I42="","",$M$9-I42) -> 20702.195 | K42: =$H$8+(I42*$E$9*$E$15/1000) -> 111.13627 | R42: =J42+89 -> 20791.195
...

Sheet DECK TALLY
B2: DECK TALLY NFQ17-8
B4: 7" 29# TSH WEDGE 563 CSG JOINTS ( 2 x Centralizers) | F4: 7" 29# TSH WEDGE 563 CSG JOINTS ( 2 x Centralizers) | J4: 7" 29# TSH WEDGE 563 PUP JOINTS | N4: Primary Shoe Track Assemblies | P4: On Cantilever deck
B5: Joint Num. | C5: Length (ft) | D5: Note | F5: Joint Num. | G5: Length (ft) | H5: Note | J5: Joint Number | K5: Length (ft) | L5: Note | N5: Items | O5: Length (ft)
A6: 1 | B6: A1 | C6: 36.57 | E6: 1 | I6: 1 | J6: Pup VP-1 | K6: 8.22 | N6: Float Shoe, DV Eccentric | O6: 3.39 | P6: QELNG-7in-FS-136-NFE
A7: =A6+1 -> 2 | B7: A2 | C7: 37.23 | E7: =E6+1 -> 2 | I7: =I6+1 -> 2 | J7: Pup VP-2 | K7: 8.22 | N7: Shoe Joint | O7: 36.86
A8: =A7+1 -> 3 | B8: A3 | C8: 37 | E8: =E7+1 -> 3 | I8: =I7+1 -> 3 | J8: Pup VP-3 | K8: 6.11
A9: =A8+1 -> 4 | B9: A4 | C9: 36.16 | E9: =E8+1 -> 4 | I9: =I8+1 -> 4 | J9: Pup VP-4 | K9: 10.25 | N9: Bttm FC Pup Joint | O9: 18.51 | P9: QELNG-7in-FC-136-NFE
A10: =A9+1 -> 5 | B10: A5 | C10: 36.91 | E10: =E9+1 -> 5 | I10: =I9+1 -> 5 | J10: Pup VP-5 | K10: 6.11 | N10: Float Collar - DV | O10: 2.91
A11: =A10+1 -> 6 | B11: A6 | C11: 35.36 | E11: =E10+1 -> 6 | I11: =I10+1 -> 6 | J11: Pup VP-6 | K11: 4.39 | N11: Top FC Pup Joint | O11: 17.53
A12: =A11+1 -> 7 | B12: A7 | C12: 36.41 | E12: =E11+1 -> 7 | I12: =I11+1 -> 7 | J12: Pup VP-7 | K12: 4.11
A13: =A12+1 -> 8 | B13: A8 | C13: 36.6 | E13: =E12+1 -> 8 | I13: =I12+1 -> 8 | J13: Pup VP-8 | K13: 18.25 | N13: Bttm Pup Joint | O13: 18.18 | P13: QELNG-7in-LC-156-NFE
A14: =A13+1 -> 9 | B14: A9 | C14: 36.48 | E14: =E13+1 -> 9 | I14: =I13+1 -> 9 | J14: Pup VP-9 | K14: 10.25 | N14: LFC Landing Collar | O14: 5.16
A15: =A14+1 -> 10 | B15: B1 | C15: 36.37 | E15: =E14+1 -> 10 | I15: =I14+1 -> 10 | J15: Pup VP-10 | K15: 18.46 | N15: Top Pup Joint | O15: 18.59
A16: =A15+1 -> 11 | B16: B2 | C16: 36.15 | E16: =E15+1 -> 11 | I16: =I15+1 -> 11 | J16: Pup VP-11 | K16: 6.26
A17: =A16+1 -> 12 | B17: B3 | C17: 34.87 | E17: =E16+1 -> 12 | I17: =I16+1 -> 12 | J17: Pup VP-12 | K17: 6.24
A18: =A17+1 -> 13 | B18: B4 | C18: 36.68 | E18: =E17+1 -> 13 | I18: =I17+1 -> 13 | J18: Pup VP-13 | K18: 10.23 | N18: Back up Shoe Track Assemblies | P18: On Cantilever deck
A19: =A18+1 -> 14 | B19: B5 | C19: 36.66 | E19: =E18+1 -> 14 | I19: =I18+1 -> 14 | J19: Pup VP-14 | K19: 10.26 | N19: Items | O19: Length (ft)
A20: =A19+1 -> 15 | B20: B6 | C20: 36.05 | E20: =E19+1 -> 15 | N20: Float Shoe, DV Eccentric | O20: 3.42 | P20: QELNG-7in-FS-150-NFE
A21: =A20+1 -> 16 | B21: B7 | C21: 36.61 | E21: =E20+1 -> 16 | N21: Shoe Joint | O21: 36.38
A22: =A21+1 -> 17 | B22: B8 | C22: 36.42 | E22: =E21+1 -> 17
A23: =A22+1 -> 18 | B23: B9 | C23: 36.67 | E23: =E22+1 -> 18 | N23: Bttm FC Pup Joint | O23: 18.19 | P23: QELNG-7in-FC-150-NFE
A24: =A23+1 -> 19 | B24: C1 | C24: 35.13 | E24: =E23+1 -> 19 | N24: Float Collar - DV | O24: 2.92
A25: =A24+1 -> 20 | B25: C2 | C25: 35.21 | E25: =E24+1 -> 20 | N25: Top FC Pup Joint | O25: 18
A26: =A25+1 -> 21 | B26: C3 | C26: 35.16 | E26: =E25+1 -> 21
A27: =A26+1 -> 22 | B27: C4 | C27: 35.17 | E27: =E26+1 -> 22 | N27: Bttm Pup Joint | O27: 18.42 | P27: QELNG-7in-LC-159-NFE
A28: =A27+1 -> 23 | B28: C5 | C28: 35.61 | E28: =E27+1 -> 23 | N28: LFC Landing Collar | O28: 5.16
A29: =A28+1 -> 24 | B29: C6 | C29: 35.46 | E29: =E28+1 -> 24 | N29: Top Pup Joint | O29: 17.95
A30: =A29+1 -> 25 | B30: C7 | C30: 34.48 | E30: =E29+1 -> 25
A31: =A30+1 -> 26 | B31: C8 | C31: 34.44 | E31: =E30+1 -> 26
A32: =A31+1 -> 27 | B32: C9 | C32: 35.63 | E32: =E31+1 -> 27
A33: =A32+1 -> 28 | B33: D1 | C33: 36.48 | E33: =E32+1 -> 28
A34: =A33+1 -> 29 | B34: D2 | C34: 35.74 | E34: =E33+1 -> 29
A35: =A34+1 -> 30 | B35: D3 | C35: 35.92 | E35: =E34+1 -> 30
A36: =A35+1 -> 31 | B36: D4 | C36: 35.65 | E36: =E35+1 -> 31
A37: =A36+1 -> 32 | B37: D5 | C37: 36.15 | E37: =E36+1 -> 32
A38: =A37+1 -> 33 | B38: D6 | C38: 35.88 | E38: =E37+1 -> 33
A39: =A38+1 -> 34 | B39: D7 | C39: 36.49 | E39: =E38+1 -> 34
A40: =A39+1 -> 35 | B40: D8 | C40: 36.39 | E40: =E39+1 -> 35
A41: =A40+1 -> 36 | B41: D9 | C41: 36.03 | E41: =E40+1 -> 36
... A86: =A85+1 -> 81 | B86: I9 | C86: 36.52 | E86: =E85+1 -> 81
...
