Workbook
Name EKIKO2: 'Liner Tally NFQ20-6'!$E$5
Name EKIKO2: #REF!

Sheet xxxxxx

Sheet Liner Tally NFQ20-6
H2: Baker Hughes | K2: Final As Run
H3: 7" LINER TALLY
C5: Tension: | D5: 929 | F5: Well: | G5: NFQ20-6 | J5: Date: | K5: 44263
C6: Burst: | D6: 11220 | F6: Rig: | G6: Shelf Drilling Odyssey | J6: QE LNG Representative: | K6: Cody/Ivan/ Ahmad
C7: Collapse: | D7: 8530 | F7: Liner Run # : | G7: 1 | J7: Baker Representative: | K7: Nurlan/JonCruz
C8: Casing Size: | D8: 7 | F8: Block Weight: | G8: 120 | J8: 7" Shoe Depth: | K8: =K9-K10 -> 21877
C9: Weight: | D9: 29 | F9: Mud Weight: | G9: 10.6 | J9: Total Depth: | K9: 21892
C10: Grade: | D10: SM2535-110 | F10: Bouyancy Factor: | G10: =(65.45-G9)/65.45 -> 0.83804431 | J10: Rat Hole: | K10: 15
C11: VAM21 M/Up Loss: | E11: 0.4055 | F11: Casing ID: | G11: 6.252 | J11: 7" Liner Top: | K11: =I307 -> 12041.133
C12: TSH M/Up Loss: | D12: 4.05 | E12: 0.3375 | F12: Connection 1: | G12: TSH Wedge 563 DPLS | J12: 9-5/8" Shoe: | K12: 12370.48
C13: Drift: | D13: 6.059 | F13: Connection 2: | J13: 9-5/8" x 10-3/4" Crossover: | K13: 1385.06
C14: Centralizers: | D14: =SUM(B17:B277) -> 504 | F14: Centralizer Type: | G14: Bow Spring
A15: JOINTS | B15: CENTRALIZERS/DESC | D15: JOINT | E15: JOINT | F15: EFFECTIVE | G15: JOINT | H15: TOTAL | I15: DEPTH OF | J15: EST STRG | K15: COMMENTS
A16: RUN | B16: NO | C16: TYPE | D16: NUMBER | E16: LENGTH | F16: LENGTH | G16: IN/OUT | H16: LENGTH | I16: TOP OF JT | J16: WEIGHT
A17: QELNG-7IN-FS-169-NFE | B17: - | C17: Float Shoe - DV | E17: 3.37 | F17: =E17 -> 3.37 | G17: =IF(E17="","OUT","IN") -> IN | H17: =F17 -> 3.37 | I17: =K8-F17 -> 21873.63 | J17: =$G$8+(H17*$D$9*$G$10/1000) -> 120.0819 | K17: DV Float Shoe: SN: 112206-112230-3 PN: H100950451GRG1
B18: 2 | C18: Shoe Joint | E18: 36.24 | F18: =E18 -> 36.24 | G18: =IF(E18="","OUT","IN") -> IN | H18: =IF(G18="IN",H17+F18,H17) -> 39.61 | I18: =IF(H18="","",$K$8-H18) -> 21837.39 | J18: =$G$8+(H18*$D$9*$G$10/1000) -> 120.96265
A19: QELNG-7IN-FC-159-NFE | B19: 1 | C19: FC Pup Joint | E19: 18.36 | F19: =E19-($D$12/12) -> 18.0225 | G19: =IF(E19="","OUT","IN") -> IN | H19: =IF(G19="IN",H18+F19,H18) -> 57.6325 | I19: =IF(H19="","",$K$8-H19) -> 21819.368 | J19: =$G$8+(H19*$D$9*$G$10/1000) -> 121.40066 | K19: DV Float Collar: PN: H101890295GRG1 SN: 110696-110679-3
B20: - | C20: Float Collar - DV | E20: 2.91 | F20: =E20 -> 2.91 | G20: =IF(E20="","OUT","IN") -> IN | H20: =IF(G20="IN",H19+F20,H19) -> 60.5425 | I20: =IF(H20="","",$K$8-H20) -> 21816.458 | J20: =$G$8+(H20*$D$9*$G$10/1000) -> 121.47138
B21: 1 | C21: FC Pup Joint | E21: 18.29 | F21: =E21 -> 18.29 | G21: =IF(E21="","OUT","IN") -> IN | H21: =IF(G21="IN",H20+F21,H20) -> 78.8325 | I21: =IF(H21="","",$K$8-H21) -> 21798.167 | J21: =$G$8+(H21*$D$9*$G$10/1000) -> 121.91589
A22: QG-7IN-LC-5KLC-02 | B22: 1 | C22: Pup Joint | E22: 18.01 | F22: =E22-($D$12/12) -> 17.6725 | G22: =IF(E22="","OUT","IN") -> IN | H22: =IF(G22="IN",H21+F22,H21) -> 96.505 | I22: =IF(H22="","",$K$8-H22) -> 21780.495 | J22: =$G$8+(H22*$D$9*$G$10/1000) -> 122.34539 | K22: LFC Landing Collar: PN: H274120438GRG1 SN:108285477-02
B23: - | C23: LFC Landing Collar | E23: 4.47 | F23: =E23 -> 4.47 | G23: =IF(E23="","OUT","IN") -> IN | H23: =IF(G23="IN",H22+F23,H22) -> 100.975 | I23: =IF(H23="","",$K$8-H23) -> 21776.025 | J23: =$G$8+(H23*$D$9*$G$10/1000) -> 122.45402
B24: 1 | C24: Pup Joint | E24: 17.63 | F24: =E24 -> 17.63 | G24: IN | H24: =IF(G24="IN",H23+F24,H23) -> 118.605 | I24: =IF(H24="","",$K$8-H24) -> 21758.395 | J24: =$G$8+(H24*$D$9*$G$10/1000) -> 122.88249
A25: 1 | B25: 2 | C25: WEDGE 563 DPLS | D25: 269 | E25: =VLOOKUP(D25,'Deck Tally'!$B$5:$C$288,2,0) -> 36.67 | F25: =E25-($D$12/12) -> 36.3325 | G25: IN | H25: =IF(G25="IN",H24+F25,H24) -> 154.9375 | I25: =IF(H25="","",$K$8-H25) -> 21722.062 | J25: =$G$8+(H25*$D$9*$G$10/1000) -> 123.76549 | K25: **BakerLok first 3ea connections
A26: 2 | B26: 2 | C26: WEDGE 563 DPLS | D26: 268 | E26: =VLOOKUP(D26,'Deck Tally'!$B$5:$C$288,2,0) -> 36.28 | F26: =E26-($D$12/12) -> 35.9425 | G26: IN | H26: =IF(G26="IN",H25+F26,H25) -> 190.88 | I26: =IF(H26="","",$K$8-H26) -> 21686.12 | J26: =$G$8+(H26*$D$9*$G$10/1000) -> 124.63901
A27: 3 | B27: 2 | C27: WEDGE 563 DPLS | D27: 267 | E27: =VLOOKUP(D27,'Deck Tally'!$B$5:$C$288,2,0) -> 37.05 | F27: =E27-($D$12/12) -> 36.7125 | G27: IN | H27: =IF(G27="IN",H26+F27,H26) -> 227.5925 | I27: =IF(H27="","",$K$8-H27) -> 21649.408 | J27: =$G$8+(H27*$D$9*$G$10/1000) -> 125.53125
B28: 1 | C28: 20 ft PUP | D28: H | E28: 20.27 | F28: =E28-($D$12/12) -> 19.9325 | G28: IN | H28: =IF(G28="IN",H27+F28,H27) -> 247.525 | I28: =IF(H28="","",$K$8-H28) -> 21629.475 | J28: =$G$8+(H28*$D$9*$G$10/1000) -> 126.01567 | K28: Planned PIP @21637ft
A29: 4 | B29: 2 | C29: WEDGE 563 DPLS | D29: 266 | E29: =VLOOKUP(D29,'Deck Tally'!$B$5:$C$288,2,0) -> 34.91 | F29: =E29-($D$12/12) -> 34.5725 | G29: IN | H29: =IF(G29="IN",H28+F29,H28) -> 282.0975 | I29: =IF(H29="","",$K$8-H29) -> 21594.903 | J29: =$G$8+(H29*$D$9*$G$10/1000) -> 126.8559 | K29: INSTALL PIP TAG #1ON JT #266 | N29: =21637-L30 -> 11.525 | O29: ft. Difference
B30: 1 | C30: WEDGE 563 DPLS | D30: S18 | E30: 36.4 | F30: =E30-($D$12/12) -> 36.0625 | G30: IN | H30: =IF(G30="IN",H29+F30,H29) -> 318.16 | I30: =IF(H30="","",$K$8-H30) -> 21558.84 | J30: =$G$8+(H30*$D$9*$G$10/1000) -> 127.73233 | K30: 4 FT above pin | L30: =I28-4 -> 21625.475
A31: 5 | B31: 2 | C31: WEDGE 563 DPLS | D31: 265 | E31: =VLOOKUP(D31,'Deck Tally'!$B$5:$C$288,2,0) -> 36.8 | F31: =E31-($D$12/12) -> 36.4625 | G31: IN | H31: =IF(G31="IN",H30+F31,H30) -> 354.6225 | I31: =IF(H31="","",$K$8-H31) -> 21522.377 | J31: =$G$8+(H31*$D$9*$G$10/1000) -> 128.61849
A32: 6 | B32: 2 | C32: WEDGE 563 DPLS | D32: 264 | E32: =VLOOKUP(D32,'Deck Tally'!$B$5:$C$288,2,0) -> 36.62 | F32: =E32-($D$12/12) -> 36.2825 | G32: IN | H32: =IF(G32="IN",H31+F32,H31) -> 390.905 | I32: =IF(H32="","",$K$8-H32) -> 21486.095 | J32: =$G$8+(H32*$D$9*$G$10/1000) -> 129.50028
A33: 7 | B33: 2 | C33: WEDGE 563 DPLS | D33: 263 | E33: =VLOOKUP(D33,'Deck Tally'!$B$5:$C$288,2,0) -> 36.52 | F33: =E33-($D$12/12) -> 36.1825 | G33: IN | H33: =IF(G33="IN",H32+F33,H32) -> 427.0875 | I33: =IF(H33="","",$K$8-H33) -> 21449.912 | J33: =$G$8+(H33*$D$9*$G$10/1000) -> 130.37963
A34: 8 | B34: 2 | C34: WEDGE 563 DPLS | D34: 262 | E34: =VLOOKUP(D34,'Deck Tally'!$B$5:$C$288,2,0) -> 36.02 | F34: =E34-($D$12/12) -> 35.6825 | G34: IN | H34: =IF(G34="IN",H33+F34,H33) -> 462.77 | I34: =IF(H34="","",$K$8-H34) -> 21414.23 | J34: =$G$8+(H34*$D$9*$G$10/1000) -> 131.24683
A35: 9 | B35: 2 | C35: WEDGE 563 DPLS | D35: 261 | E35: =VLOOKUP(D35,'Deck Tally'!$B$5:$C$288,2,0) -> 36.39 | F35: =E35-($D$12/12) -> 36.0525 | G35: IN | H35: =IF(G35="IN",H34+F35,H34) -> 498.8225 | I35: =IF(H35="","",$K$8-H35) -> 21378.178 | J35: =$G$8+(H35*$D$9*$G$10/1000) -> 132.12303
A36: 10 | B36: 2 | C36: WEDGE 563 DPLS | D36: 260 | E36: =VLOOKUP(D36,'Deck Tally'!$B$5:$C$288,2,0) -> 37.15 | F36: =E36-($D$12/12) -> 36.8125 | G36: IN | H36: =IF(G36="IN",H35+F36,H35) -> 535.635 | I36: =IF(H36="","",$K$8-H36) -> 21341.365 | J36: =$G$8+(H36*$D$9*$G$10/1000) -> 133.01769
A37: 11 | B37: 2 | C37: WEDGE 563 DPLS | D37: 259 | E37: =VLOOKUP(D37,'Deck Tally'!$B$5:$C$288,2,0) -> 36.37 | F37: =E37-($D$12/12) -> 36.0325 | G37: IN | H37: =IF(G37="IN",H36+F37,H36) -> 571.6675 | I37: =IF(H37="","",$K$8-H37) -> 21305.333 | J37: =$G$8+(H37*$D$9*$G$10/1000) -> 133.8934
A38: 12 | B38: 2 | C38: WEDGE 563 DPLS | D38: 258 | E38: =VLOOKUP(D38,'Deck Tally'!$B$5:$C$288,2,0) -> 34.69 | F38: =E38-($D$12/12) -> 34.3525 | G38: IN | H38: =IF(G38="IN",H37+F38,H37) -> 606.02 | I38: =IF(H38="","",$K$8-H38) -> 21270.98 | J38: =$G$8+(H38*$D$9*$G$10/1000) -> 134.72828
A39: 13 | B39: 2 | C39: WEDGE 563 DPLS | D39: 257 | E39: =VLOOKUP(D39,'Deck Tally'!$B$5:$C$288,2,0) -> 37.05 | F39: =E39-($D$12/12) -> 36.7125 | G39: IN | H39: =IF(G39="IN",H38+F39,H38) -> 642.7325 | I39: =IF(H39="","",$K$8-H39) -> 21234.268 | J39: =$G$8+(H39*$D$9*$G$10/1000) -> 135.62051
A40: 14 | B40: 2 | C40: WEDGE 563 DPLS | D40: 256 | E40: =VLOOKUP(D40,'Deck Tally'!$B$5:$C$288,2,0) -> 37.51 | F40: =E40-($D$12/12) -> 37.1725 | G40: IN | H40: =IF(G40="IN",H39+F40,H39) -> 679.905 | I40: =IF(H40="","",$K$8-H40) -> 21197.095 | J40: =$G$8+(H40*$D$9*$G$10/1000) -> 136.52392
A41: 15 | B41: 2 | C41: WEDGE 563 DPLS | D41: 255 | E41: =VLOOKUP(D41,'Deck Tally'!$B$5:$C$288,2,0) -> 36.75 | F41: =E41-($D$12/12) -> 36.4125 | G41: IN | H41: =IF(G41="IN",H40+F41,H40) -> 716.3175 | I41: =IF(H41="","",$K$8-H41) -> 21160.682 | J41: =$G$8+(H41*$D$9*$G$10/1000) -> 137.40887
A42: 16 | B42: 2 | C42: WEDGE 563 DPLS | D42: 254 | E42: =VLOOKUP(D42,'Deck Tally'!$B$5:$C$288,2,0) -> 37.08 | F42: =E42-($D$12/12) -> 36.7425 | G42: IN | H42: =IF(G42="IN",H41+F42,H41) -> 753.06 | I42: =IF(H42="","",$K$8-H42) -> 21123.94 | J42: =$G$8+(H42*$D$9*$G$10/1000) -> 138.30183
...

Sheet Deck Tally
B2: 7" 29# TSH Wedge563 CSG JOINTS (2xCentralizers) | F2: 7" 29# TSH Wedge563 PUP JOINTS
F3: Joint Number | G3: Length (ft) | H3: Note
B4: Deck # | C4: Length (ft) | D4: Location | F4: A | G4: 10.26 | H4: Used
A5: 1 | B5: 1 | C5: 36.06 | F5: B | G5: 10.3 | H5: Used
A6: 2 | B6: 2 | C6: 36.47 | F6: C | G6: 10.53
A7: 3 | B7: 3 | C7: 36.09 | F7: D | G7: 10.26
A8: 4 | B8: 4 | C8: 35.85 | F8: E | G8: 10.25
A9: 5 | B9: 5 | C9: 36.5 | F9: F | G9: 10.54
A10: 6 | B10: 6 | C10: 36.58 | F10: G | G10: 10.26
A11: 7 | B11: 7 | C11: 36.47
A12: 8 | B12: 8 | C12: 36.51 | F12: H | G12: 20.27 | H12: Used
A13: 9 | B13: 9 | C13: 36.17 | F13: I | G13: 20.24 | H13: Used
A14: 10 | B14: 10 | C14: 36.2 | F14: J | G14: 20.26
A15: 11 | B15: 11 | C15: 37.31 | F15: K | G15: 20.25
A16: 12 | B16: 12 | C16: 36.56 | F16: L | G16: 20.2
A17: 13 | B17: 13 | C17: 36.46 | F17: M | G17: 20.25
A18: 14 | B18: 14 | C18: 36.56
A19: 15 | B19: 15 | C19: 36.62
A20: 16 | B20: 16 | C20: 36.38
A21: 17 | B21: 17 | C21: 37.02
A22: 18 | B22: 18 | C22: 36.77
A23: 19 | B23: 19 | C23: 37.29
A24: 20 | B24: 20 | C24: 36.44
A25: 21 | B25: 21 | C25: 36.61
A26: 22 | B26: 22 | C26: 36.86
A27: 23 | B27: 23 | C27: 36.2
A28: 24 | B28: 24 | C28: 36.19
A29: 25 | B29: 25 | C29: 36.54
... A273: 269 | B273: 269 | C273: 36.67
A274: 270 | B274: 270
A275: 271 | B275: 271
A276: 272 | B276: 272
A277: 273 | B277: 273
A278: 274 | B278: 274
A279: 275 | B279: 275
A280: 276 | B280: 276
A281: 277 | B281: 277
A282: 278 | B282: 278
A283: 279 | B283: 279
A284: 280 | B284: S10 | C284: 36.63
...
