Workbook
Name ___add1: #REF!
Name ___add2: #REF!
Name ___add3: #REF!
Name ___add4: #REF!
Name ___add5: #REF!
Name ___add6: #REF!
Name ___add7: #REF!
Name ___add8: #REF!
Name ___add9: #REF!
Name ___cem20: #REF!
Name ___cem30: #REF!
Name ___tot13: #REF!
Name ___tot30: #REF!
Name ___tot7: #REF!
Name ___tot9: #REF!
Name ___xs20: #REF!
Name __add1: #REF!
Name __add2: #REF!
Name __add3: #REF!
Name __add4: #REF!
Name __add5: #REF!
Name __add6: #REF!
Name __add7: #REF!
Name __add8: #REF!
Name __add9: #REF!
Name __cem20: #REF!
Name __cem30: #REF!
Name __NFQ6: #REF!
Name __tot13: #REF!
Name __tot30: #REF!
Name __tot7: #REF!
Name __tot9: #REF!
Name __xs20: #REF!
Name _58_D124_bwoc: NA()
Name _58_D124_bwoc_1: NA()
Name _58_XE825_bwoc: NA()
Name _58_XE825_bwoc_1: NA()
Name _add1: NA()
Name _add1_1: NA()
Name _add2: NA()
Name _add2_1: NA()
Name _add3: NA()
Name _add3_1: NA()
Name _add4: NA()
Name _add4_1: NA()
Name _add5: NA()
Name _add5_1: NA()
Name _add6: NA()
Name _add6_1: NA()
Name _add7: NA()
Name _add7_1: NA()
Name _add8: NA()
Name _add8_1: NA()
Name _add9: NA()
Name _add9_1: NA()
Name _cem20: NA()
Name _cem20_1: NA()
Name _cem30: NA()
Name _cem30_1: NA()
Name _Fill: NA()

Sheet 7" Liner Tally NFQ22-9 (2)
E2: BAKER HUGHES 7" LINER TALLY
D5: Tension: | E5: 929 Klbs | G5: Well: | H5: NFQ 22-09
D6: Burst: | E6: 11220 | G6: Rig: | H6: Lovando | K6: Date: | L6: 45754
D7: Collapse: | E7: 8530 | G7: Liner Run #: | H7: 1 | K7: Qatar Gas Reps: | L7: Travis Romanko / Remco Roomer/ Handi C
D8: Casing Size: | E8: 7 | G8: Block Weight: | H8: 85 | K8: Baker Hughes Reps: | L8: Mohammed Bounehidaj/ Venkidesa Kumar
A9: Shoe Track Joints : | D9: Weight: | E9: 29 | G9: Drift: | H9: 6.059 in | M9: 27.58
A10: TSH Wedge 563® | D10: Connection Type 1: | E10: VAMTOP HC | G10: Connection Type 2: | H10: VAM 21 HT-NX | K10: Shoe Depth: | L10: =SUM(L11-L12) -> 21355
A11: Grade: SANICRO 28-110 | D11: Grade: | E11: SM2535-110 | G11: Grade: | H11: SM2535-110 | K11: Total Depth: | L11: 21365
A12: M/Up loss: | B12: 4.05 | D12: Make Up Loss: | E12: 4.776 | G12: Make Up Loss: | H12: 4.866 | K12: Rat Hole: | L12: 10
A13: Casing ID: 6.250 in | D13: Casing ID: | E13: 6.25 | G13: Casing ID: | H13: 6.25 | K13: Top of 7" Liner: | L13: =J333 -> 11528.421
D14: Mud Weight: | E14: 12.3 | G14: Centralizers Type: | H14: Purple-X Bow Spring | K14: 9-5/8" Shoe: | L14: 11860 | M14: Pump Output
D15: BF: | E15: =(65.45-E14)/65.45 -> 0.81207028 | G15: Total Centralizers: | H15: =SUM(C18:C320) -> 580 | K15: 9-5/8" x 10-3/4" Crossover: | L15: 1283.32 ft. | M15: 0.119
A16: DESCRIPTION | C16: CENTRALIZERS | E16: DECK | F16: JOINT | G16: EFFECTIVE | H16: JOINT | I16: TOTAL | J16: DEPTH OF | K16: EST STRG | L16: COMMENTS
C17: No. | D17: TYPE | E17: NUM. | F17: LENGTH | G17: LENGTH | H17: IN/OUT | I17: LENGTH | J17: TOP OF JT | K17: WEIGHT | L17: COMMENTS
A18: FLOAT SHOE ASSY - A QELNG-7in-FS-171-NFE | C18: A | D18: Float Shoe - Double Valve, Eccentric | F18: ='DECK TALLY'!K6 -> 3.37 | G18: =SUM('DECK TALLY'!K6) -> 3.37 | H18: IN | I18: =G18 -> 3.37 | J18: =L10-G18 -> 21351.63 | K18: =$H$8+(I18*$E$9*$E$15/1000) -> 85.079364 | L18: PN: H100950451GRG1, SN: 112201-112227-6 Max OD: 7.729", 29#, L80
C19: 2 | D19: Shoe Jt - TSH Wedge 563 | F19: =SUM('DECK TALLY'!K7) -> 37.2 | G19: =SUM('DECK TALLY'!K7) -> 37.2 | H19: IN | I19: =IF(H19="IN",I18+G19,I18) -> 40.57 | J19: =IF(I19="","",$L$10-I19) -> 21314.43 | K19: =$H$8+(I19*$E$9*$E$15/1000) -> 85.955425
A20: FLOAT COLLAR ASSY - A QELNG-7in-FC-171-NFE | C20: 1 | D20: Bttm Pup Jt. - TSH Wedge 563 | F20: =SUM('DECK TALLY'!K9) -> 20.26 | G20: =F20-(B12/12) -> 19.9225 | H20: IN | I20: =IF(H20="IN",I19+G20,I19) -> 60.4925 | J20: =IF(I20="","",$L$10-I20) -> 21294.507 | K20: =$H$8+(I20*$E$9*$E$15/1000) -> 86.424601 | L20: PN: H101890295GRG1, SN: 112195 - 112218-2 Max OD: 7.705", 29#, L80
C21: A | D21: Float Collar - Double Valve | F21: =SUM('DECK TALLY'!K10) -> 2.91 | G21: =F21 -> 2.91 | H21: IN | I21: =IF(H21="IN",I20+G21,I20) -> 63.4025 | J21: =IF(I21="","",$L$10-I21) -> 21291.597 | K21: =$H$8+(I21*$E$9*$E$15/1000) -> 86.493131
C22: 1 | D22: Top Pup Jt. - TSH Wedge 563 | F22: =SUM('DECK TALLY'!K11) -> 19.9 | G22: =F22 -> 19.9 | H22: IN | I22: =IF(H22="IN",I21+G22,I21) -> 83.3025 | J22: =IF(I22="","",$L$10-I22) -> 21271.697 | K22: =$H$8+(I22*$E$9*$E$15/1000) -> 86.961777
A23: LANDING COLLAR QELNG-7in-LC-172-NFE-VTHC | C23: 1 | D23: Bttm Pup Jt. - TSH Wedge 563 | F23: =SUM('DECK TALLY'!K13) -> 18.35 | G23: =F23-(B12/12) -> 18.0125 | H23: IN | I23: =IF(H23="IN",I22+G23,I22) -> 101.315 | J23: =IF(I23="","",$L$10-I23) -> 21253.685 | K23: =$H$8+(I23*$E$9*$E$15/1000) -> 87.385972 | L23: LFC Landing Collar (Ball Seat Sheared) PN: H274120438GRG1, SN: 108656274-05, Max OD: 7.676"
C24: A | D24: LFC Landing Collar | F24: =SUM('DECK TALLY'!K14) -> 4.41 | G24: =F24 -> 4.41 | H24: IN | I24: =IF(H24="IN",I23+G24,I23) -> 105.725 | J24: =IF(I24="","",$L$10-I24) -> 21249.275 | K24: =$H$8+(I24*$E$9*$E$15/1000) -> 87.489828
C25: 1 | D25: Top Pup Jt. - TSH Wedge 563 | F25: =SUM('DECK TALLY'!K15) -> 17.47 | G25: =F25 -> 17.47 | H25: IN | I25: =IF(H25="IN",I24+G25,I24) -> 123.195 | J25: =IF(I25="","",$L$10-I25) -> 21231.805 | K25: =$H$8+(I25*$E$9*$E$15/1000) -> 87.901247
C26: - | D26: Crossover - TSH Wedge 563 Pin Dwn x VAM TOP HC Box Up | F26: =SUM('DECK TALLY'!K16) -> 5.48 | G26: =F26 -> 5.48 | H26: IN | I26: =IF(H26="IN",I25+G26,I25) -> 128.675 | J26: =IF(I26="","",$L$10-I26) -> 21226.325 | K26: =$H$8+(I26*$E$9*$E$15/1000) -> 88.030301
A27: QELNG-7in-XO-32-NFE VTHC | C27: 7" VAM TOP HC FULL JOINT B x P | F27: =SUM('DECK TALLY'!K18) -> 33.35 | G27: =F27-(4.776/12) -> 32.952 | H27: IN | I27: =IF(H27="IN",I26+G27,I26) -> 161.627 | J27: =IF(I27="","",$L$10-I27) -> 21193.373 | K27: =$H$8+(I27*$E$9*$E$15/1000) -> 88.806322
C28: 7" XOVER VAM TOP HT- PIN DOWN x VAM 21 HT-NX BOX UP | F28: =SUM('DECK TALLY'!K19) -> 5.35 | G28: =F28 -> 5.35 | H28: IN | I28: =IF(H28="IN",I27+G28,I27) -> 166.977 | J28: =IF(I28="","",$L$10-I28) -> 21188.023 | K28: =$H$8+(I28*$E$9*$E$15/1000) -> 88.932315
A29: Vam 21 HT NX | C29: 2 | D29: Bow Spring | E29: ='DECK TALLY'!B6 -> 1 | F29: ='DECK TALLY'!C6 -> 33.75 | G29: =F29-($H$12/12) -> 33.3445 | H29: IN | I29: =IF(H29="IN",I28+G29,I28) -> 200.3215 | J29: =IF(I29="","",$L$10-I29) -> 21154.679 | K29: =$H$8+(I29*$E$9*$E$15/1000) -> 89.717579 | L29: PIP TAG # 7 ON JT# 2 | N29: Pip Tag Proposed Depth
A30: 20ft Pup Joint | C30: 1 | D30: Bow Spring | E30: ='DECK TALLY'!F11 -> P 6 | F30: ='DECK TALLY'!G11 -> 20.2 | G30: =F30-($H$12/12) -> 19.7945 | H30: IN | I30: =IF(H30="IN",I29+G30,I29) -> 220.116 | J30: =IF(I30="","",$L$10-I30) -> 21134.884 | K30: =$H$8+(I30*$E$9*$E$15/1000) -> 90.18374 | L30: PIP TAG # 7 INSTALLED 4 ft FROM PIN END
A31: Vam 21 HT NX | C31: 2 | D31: Bow Spring | E31: ='DECK TALLY'!B7 -> 2 | F31: ='DECK TALLY'!C7 -> 33.94 | G31: =F31-($H$12/12) -> 33.5345 | H31: IN | I31: =IF(H31="IN",I30+G31,I30) -> 253.6505 | J31: =IF(I31="","",$L$10-I31) -> 21101.35 | K31: =$H$8+(I31*$E$9*$E$15/1000) -> 90.973479 | L31: Pip Tag DEPTH : | M31: =SUM(J30-4) -> 21130.884 | N31: 21100
A32: Vam 21 HT NX | C32: 1 | D32: Bow Spring | E32: ='DECK TALLY'!B8 -> 3 | F32: =VLOOKUP(E32,'DECK TALLY'!$B$6:$C$316,2,FALSE) -> 33.94 | G32: =F32-($H$12/12) -> 33.5345 | H32: IN | I32: =IF(H32="IN",I31+G32,I31) -> 287.185 | J32: =IF(I32="","",$L$10-I32) -> 21067.815 | K32: =$H$8+(I32*$E$9*$E$15/1000) -> 91.763218 | L32: below K3 perfs - Cont. EZSV correlation | N32: =M31-N31 -> 30.884
A33: Vam 21 HT NX | C33: 2 | D33: Bow Spring | E33: ='DECK TALLY'!B9 -> 4 | F33: =VLOOKUP(E33,'DECK TALLY'!$B$6:$C$316,2,FALSE) -> 33.9 | G33: =F33-($H$12/12) -> 33.4945 | H33: IN | I33: =IF(H33="IN",I32+G33,I32) -> 320.6795 | J33: =IF(I33="","",$L$10-I33) -> 21034.321 | K33: =$H$8+(I33*$E$9*$E$15/1000) -> 92.552014 | L33: Remove 1 x centralizer from jt # 3
A34: Vam 21 HT NX | C34: 2 | D34: Bow Spring | E34: ='DECK TALLY'!B10 -> 5 | F34: =VLOOKUP(E34,'DECK TALLY'!$B$6:$C$316,2,FALSE) -> 33.89 | G34: =F34-($H$12/12) -> 33.4845 | H34: IN | I34: =IF(H34="IN",I33+G34,I33) -> 354.164 | J34: =IF(I34="","",$L$10-I34) -> 21000.836 | K34: =$H$8+(I34*$E$9*$E$15/1000) -> 93.340576
A35: Vam 21 HT NX | C35: 2 | D35: Bow Spring | E35: ='DECK TALLY'!B11 -> 6 | F35: =VLOOKUP(E35,'DECK TALLY'!$B$6:$C$316,2,FALSE) -> 33.52 | G35: =F35-($H$12/12) -> 33.1145 | H35: IN | I35: =IF(H35="IN",I34+G35,I34) -> 387.2785 | J35: =IF(I35="","",$L$10-I35) -> 20967.721 | K35: =$H$8+(I35*$E$9*$E$15/1000) -> 94.120423
A36: Vam 21 HT NX | C36: 2 | D36: Bow Spring | E36: ='DECK TALLY'!B12 -> 7 | F36: =VLOOKUP(E36,'DECK TALLY'!$B$6:$C$316,2,FALSE) -> 32.45 | G36: =F36-($H$12/12) -> 32.0445 | H36: IN | I36: =IF(H36="IN",I35+G36,I35) -> 419.323 | J36: =IF(I36="","",$L$10-I36) -> 20935.677 | K36: =$H$8+(I36*$E$9*$E$15/1000) -> 94.875073
A37: Vam 21 HT NX | C37: 2 | D37: Bow Spring | E37: ='DECK TALLY'!B13 -> 8 | F37: =VLOOKUP(E37,'DECK TALLY'!$B$6:$C$316,2,FALSE) -> 33.77 | G37: =F37-($H$12/12) -> 33.3645 | H37: IN | I37: =IF(H37="IN",I36+G37,I36) -> 452.6875 | J37: =IF(I37="","",$L$10-I37) -> 20902.312 | K37: =$H$8+(I37*$E$9*$E$15/1000) -> 95.660808
A38: Vam 21 HT NX | C38: 2 | D38: Bow Spring | E38: ='DECK TALLY'!B14 -> 9 | F38: =VLOOKUP(E38,'DECK TALLY'!$B$6:$C$316,2,FALSE) -> 33.4 | G38: =F38-($H$12/12) -> 32.9945 | H38: IN | I38: =IF(H38="IN",I37+G38,I37) -> 485.682 | J38: =IF(I38="","",$L$10-I38) -> 20869.318 | K38: =$H$8+(I38*$E$9*$E$15/1000) -> 96.43783
A39: Vam 21 HT NX | C39: 2 | D39: Bow Spring | E39: ='DECK TALLY'!B15 -> 10 | F39: =VLOOKUP(E39,'DECK TALLY'!$B$6:$C$316,2,FALSE) -> 33.83 | G39: =F39-($H$12/12) -> 33.4245 | H39: IN | I39: =IF(H39="IN",I38+G39,I38) -> 519.1065 | J39: =IF(I39="","",$L$10-I39) -> 20835.893 | K39: =$H$8+(I39*$E$9*$E$15/1000) -> 97.224978
A40: Vam 21 HT NX | C40: 2 | D40: Bow Spring | E40: ='DECK TALLY'!B16 -> 11 | F40: =VLOOKUP(E40,'DECK TALLY'!$B$6:$C$316,2,FALSE) -> 33.79 | G40: =F40-($H$12/12) -> 33.3845 | H40: IN | I40: =IF(H40="IN",I39+G40,I39) -> 552.491 | J40: =IF(I40="","",$L$10-I40) -> 20802.509 | K40: =$H$8+(I40*$E$9*$E$15/1000) -> 98.011184
A41: Vam 21 HT NX | C41: 2 | D41: Bow Spring | E41: ='DECK TALLY'!B17 -> 12 | F41: =VLOOKUP(E41,'DECK TALLY'!$B$6:$C$316,2,FALSE) -> 33.94 | G41: =F41-($H$12/12) -> 33.5345 | H41: IN | I41: =IF(H41="IN",I40+G41,I40) -> 586.0255 | J41: =IF(I41="","",$L$10-I41) -> 20768.975 | K41: =$H$8+(I41*$E$9*$E$15/1000) -> 98.800923
A42: Vam 21 HT NX | C42: 2 | D42: Bow Spring | E42: ='DECK TALLY'!B18 -> 13 | F42: =VLOOKUP(E42,'DECK TALLY'!$B$6:$C$316,2,FALSE) -> 33.85 | G42: =F42-($H$12/12) -> 33.4445 | H42: IN | I42: =IF(H42="IN",I41+G42,I41) -> 619.47 | J42: =IF(I42="","",$L$10-I42) -> 20735.53 | K42: =$H$8+(I42*$E$9*$E$15/1000) -> 99.588542
A43: Vam 21 HT NX | C43: 2 | D43: Bow Spring | E43: ='DECK TALLY'!B19 -> 14 | F43: =VLOOKUP(E43,'DECK TALLY'!$B$6:$C$316,2,FALSE) -> 33.55 | G43: =F43-($H$12/12) -> 33.1445 | H43: IN | I43: =IF(H43="IN",I42+G43,I42) -> 652.6145 | J43: =IF(I43="","",$L$10-I43) -> 20702.386 | K43: =$H$8+(I43*$E$9*$E$15/1000) -> 100.3691
...

Sheet 7" Liner Tally NFQ22-9
E2: BAKER HUGHES 7" LINER TALLY
D5: Tension: | E5: 929 Klbs | G5: Well: | H5: NFQ 22-09
D6: Burst: | E6: 11220 | G6: Rig: | H6: Lovando | L6: Date: | M6: 45754
D7: Collapse: | E7: 8530 | G7: Liner Run #: | H7: 1 | L7: Qatar Gas Reps: | M7: Travis Romanko / Remco Roomer/ Handi C
D8: Casing Size: | E8: 7 | G8: Block Weight: | H8: 85 | L8: Baker Hughes Reps: | M8: Mohammed Bounehidaj/ Venkidesa Kumar
A9: Shoe Track Joints : | D9: Weight: | E9: 29 | G9: Drift: | H9: 6.059 in | N9: 27.58
A10: TSH Wedge 563® | D10: Connection Type 1: | E10: VAMTOP HC | G10: Connection Type 2: | H10: VAM 21 HT-NX | L10: Shoe Depth: | M10: =SUM(M11-M12) -> 21355
A11: Grade: SANICRO 28-110 | D11: Grade: | E11: SM2535-110 | G11: Grade: | H11: SM2535-110 | L11: Total Depth: | M11: 21365
A12: M/Up loss: | B12: 4.05 | D12: Make Up Loss: | E12: 4.776 | G12: Make Up Loss: | H12: 4.866 | L12: Rat Hole: | M12: 10
A13: Casing ID: 6.250 in | D13: Casing ID: | E13: 6.25 | G13: Casing ID: | H13: 6.25 | L13: Top of 7" Liner: | M13: =J333 -> 11528.421
D14: Mud Weight: | E14: 12.3 | G14: Centralizers Type: | H14: Purple-X Bow Spring | L14: 9-5/8" Shoe: | M14: 11860 | N14: Pump Output
D15: BF: | E15: =(65.45-E14)/65.45 -> 0.81207028 | G15: Total Centralizers: | H15: =SUM(C18:C320) -> 580 | L15: 9-5/8" x 10-3/4" Crossover: | M15: 1283.32 ft. | N15: 0.119
A16: DESCRIPTION | C16: CENTRALIZERS | E16: DECK | F16: JOINT | G16: EFFECTIVE | H16: JOINT | I16: TOTAL | J16: DEPTH OF | L16: EST STRG | M16: COMMENTS
C17: No. | D17: TYPE | E17: NUM. | F17: LENGTH | G17: LENGTH | H17: IN/OUT | I17: LENGTH | J17: TOP OF JT | L17: WEIGHT | M17: COMMENTS
A18: FLOAT SHOE ASSY - A QELNG-7in-FS-171-NFE | C18: A | D18: Float Shoe - Double Valve, Eccentric | F18: ='DECK TALLY'!K6 -> 3.37 | G18: =SUM('DECK TALLY'!K6) -> 3.37 | H18: IN | I18: =G18 -> 3.37 | J18: =M10-G18 -> 21351.63 | M18: PN: H100950451GRG1, SN: 112201-112227-6 Max OD: 7.729", 29#, L80
C19: 2 | D19: Shoe Jt - TSH Wedge 563 | F19: =SUM('DECK TALLY'!K7) -> 37.2 | G19: =SUM('DECK TALLY'!K7) -> 37.2 | H19: IN | I19: =IF(H19="IN",I18+G19,I18) -> 40.57 | J19: =IF(I19="","",$M$10-I19) -> 21314.43
A20: FLOAT COLLAR ASSY - A QELNG-7in-FC-171-NFE | C20: 1 | D20: Bttm Pup Jt. - TSH Wedge 563 | F20: =SUM('DECK TALLY'!K9) -> 20.26 | G20: =F20-(B12/12) -> 19.9225 | H20: IN | I20: =IF(H20="IN",I19+G20,I19) -> 60.4925 | J20: =IF(I20="","",$M$10-I20) -> 21294.507 | M20: PN: H101890295GRG1, SN: 112195 - 112218-2 Max OD: 7.705", 29#, L80
C21: A | D21: Float Collar - Double Valve | F21: =SUM('DECK TALLY'!K10) -> 2.91 | G21: =F21 -> 2.91 | H21: IN | I21: =IF(H21="IN",I20+G21,I20) -> 63.4025 | J21: =IF(I21="","",$M$10-I21) -> 21291.597
C22: 1 | D22: Top Pup Jt. - TSH Wedge 563 | F22: =SUM('DECK TALLY'!K11) -> 19.9 | G22: =F22 -> 19.9 | H22: IN | I22: =IF(H22="IN",I21+G22,I21) -> 83.3025 | J22: =IF(I22="","",$M$10-I22) -> 21271.697
A23: LANDING COLLAR QELNG-7in-LC-172-NFE-VTHC | C23: 1 | D23: Bttm Pup Jt. - TSH Wedge 563 | F23: =SUM('DECK TALLY'!K13) -> 18.35 | G23: =F23-(B12/12) -> 18.0125 | H23: IN | I23: =IF(H23="IN",I22+G23,I22) -> 101.315 | J23: =IF(I23="","",$M$10-I23) -> 21253.685 | M23: LFC Landing Collar (Ball Seat Sheared) PN: H274120438GRG1, SN: 108656274-05, Max OD: 7.676"
C24: A | D24: LFC Landing Collar | F24: =SUM('DECK TALLY'!K14) -> 4.41 | G24: =F24 -> 4.41 | H24: IN | I24: =IF(H24="IN",I23+G24,I23) -> 105.725 | J24: =IF(I24="","",$M$10-I24) -> 21249.275
C25: 1 | D25: Top Pup Jt. - TSH Wedge 563 | F25: =SUM('DECK TALLY'!K15) -> 17.47 | G25: =F25 -> 17.47 | H25: IN | I25: =IF(H25="IN",I24+G25,I24) -> 123.195 | J25: =IF(I25="","",$M$10-I25) -> 21231.805
C26: - | D26: Crossover - TSH Wedge 563 Pin Dwn x VAM TOP HC Box Up | F26: =SUM('DECK TALLY'!K16) -> 5.48 | G26: =F26 -> 5.48 | H26: IN | I26: =IF(H26="IN",I25+G26,I25) -> 128.675 | J26: =IF(I26="","",$M$10-I26) -> 21226.325
A27: QELNG-7in-XO-32-NFE VTHC | C27: 7" VAM TOP HC FULL JOINT B x P | F27: =SUM('DECK TALLY'!K18) -> 33.35 | G27: =F27-(4.776/12) -> 32.952 | H27: IN | I27: =IF(H27="IN",I26+G27,I26) -> 161.627 | J27: =IF(I27="","",$M$10-I27) -> 21193.373
C28: 7" XOVER VAM TOP HT- PIN DOWN x VAM 21 HT-NX BOX UP | F28: =SUM('DECK TALLY'!K19) -> 5.35 | G28: =F28 -> 5.35 | H28: IN | I28: =IF(H28="IN",I27+G28,I27) -> 166.977 | J28: =IF(I28="","",$M$10-I28) -> 21188.023
A29: Vam 21 HT NX | C29: 2 | D29: Bow Spring | E29: ='DECK TALLY'!B6 -> 1 | F29: ='DECK TALLY'!C6 -> 33.75 | G29: =F29-($H$12/12) -> 33.3445 | H29: IN | I29: =IF(H29="IN",I28+G29,I28) -> 200.3215 | J29: =IF(I29="","",$M$10-I29) -> 21154.679 | M29: PIP TAG # 7 ON JT# 2 | O29: Pip Tag Proposed Depth
A30: 20ft Pup Joint | C30: 1 | D30: Bow Spring | E30: ='DECK TALLY'!F11 -> P 6 | F30: ='DECK TALLY'!G11 -> 20.2 | G30: =F30-($H$12/12) -> 19.7945 | H30: IN | I30: =IF(H30="IN",I29+G30,I29) -> 220.116 | J30: =IF(I30="","",$M$10-I30) -> 21134.884 | M30: PIP TAG # 7 INSTALLED 4 ft FROM PIN END
A31: Vam 21 HT NX | C31: 2 | D31: Bow Spring | E31: ='DECK TALLY'!B7 -> 2 | F31: ='DECK TALLY'!C7 -> 33.94 | G31: =F31-($H$12/12) -> 33.5345 | H31: IN | I31: =IF(H31="IN",I30+G31,I30) -> 253.6505 | J31: =IF(I31="","",$M$10-I31) -> 21101.35 | M31: Pip Tag DEPTH : | N31: =SUM(J30-4) -> 21130.884 | O31: 21100
A32: Vam 21 HT NX | C32: 1 | D32: Bow Spring | E32: ='DECK TALLY'!B8 -> 3 | F32: =VLOOKUP(E32,'DECK TALLY'!$B$6:$C$316,2,FALSE) -> 33.94 | G32: =F32-($H$12/12) -> 33.5345 | H32: IN | I32: =IF(H32="IN",I31+G32,I31) -> 287.185 | J32: =IF(I32="","",$M$10-I32) -> 21067.815 | M32: below K3 perfs - Cont. EZSV correlation | O32: =N31-O31 -> 30.884
A33: Vam 21 HT NX | C33: 2 | D33: Bow Spring | E33: ='DECK TALLY'!B9 -> 4 | F33: =VLOOKUP(E33,'DECK TALLY'!$B$6:$C$316,2,FALSE) -> 33.9 | G33: =F33-($H$12/12) -> 33.4945 | H33: IN | I33: =IF(H33="IN",I32+G33,I32) -> 320.6795 | J33: =IF(I33="","",$M$10-I33) -> 21034.321 | M33: Remove 1 x centralizer from jt # 3
A34: Vam 21 HT NX | C34: 2 | D34: Bow Spring | E34: ='DECK TALLY'!B10 -> 5 | F34: =VLOOKUP(E34,'DECK TALLY'!$B$6:$C$316,2,FALSE) -> 33.89 | G34: =F34-($H$12/12) -> 33.4845 | H34: IN | I34: =IF(H34="IN",I33+G34,I33) -> 354.164 | J34: =IF(I34="","",$M$10-I34) -> 21000.836
A35: Vam 21 HT NX | C35: 2 | D35: Bow Spring | E35: ='DECK TALLY'!B11 -> 6 | F35: =VLOOKUP(E35,'DECK TALLY'!$B$6:$C$316,2,FALSE) -> 33.52 | G35: =F35-($H$12/12) -> 33.1145 | H35: IN | I35: =IF(H35="IN",I34+G35,I34) -> 387.2785 | J35: =IF(I35="","",$M$10-I35) -> 20967.721
A36: Vam 21 HT NX | C36: 2 | D36: Bow Spring | E36: ='DECK TALLY'!B12 -> 7 | F36: =VLOOKUP(E36,'DECK TALLY'!$B$6:$C$316,2,FALSE) -> 32.45 | G36: =F36-($H$12/12) -> 32.0445 | H36: IN | I36: =IF(H36="IN",I35+G36,I35) -> 419.323 | J36: =IF(I36="","",$M$10-I36) -> 20935.677
A37: Vam 21 HT NX | C37: 2 | D37: Bow Spring | E37: ='DECK TALLY'!B13 -> 8 | F37: =VLOOKUP(E37,'DECK TALLY'!$B$6:$C$316,2,FALSE) -> 33.77 | G37: =F37-($H$12/12) -> 33.3645 | H37: IN | I37: =IF(H37="IN",I36+G37,I36) -> 452.6875 | J37: =IF(I37="","",$M$10-I37) -> 20902.312
A38: Vam 21 HT NX | C38: 2 | D38: Bow Spring | E38: ='DECK TALLY'!B14 -> 9 | F38: =VLOOKUP(E38,'DECK TALLY'!$B$6:$C$316,2,FALSE) -> 33.4 | G38: =F38-($H$12/12) -> 32.9945 | H38: IN | I38: =IF(H38="IN",I37+G38,I37) -> 485.682 | J38: =IF(I38="","",$M$10-I38) -> 20869.318
A39: Vam 21 HT NX | C39: 2 | D39: Bow Spring | E39: ='DECK TALLY'!B15 -> 10 | F39: =VLOOKUP(E39,'DECK TALLY'!$B$6:$C$316,2,FALSE) -> 33.83 | G39: =F39-($H$12/12) -> 33.4245 | H39: IN | I39: =IF(H39="IN",I38+G39,I38) -> 519.1065 | J39: =IF(I39="","",$M$10-I39) -> 20835.893
A40: Vam 21 HT NX | C40: 2 | D40: Bow Spring | E40: ='DECK TALLY'!B16 -> 11 | F40: =VLOOKUP(E40,'DECK TALLY'!$B$6:$C$316,2,FALSE) -> 33.79 | G40: =F40-($H$12/12) -> 33.3845 | H40: IN | I40: =IF(H40="IN",I39+G40,I39) -> 552.491 | J40: =IF(I40="","",$M$10-I40) -> 20802.509
A41: Vam 21 HT NX | C41: 2 | D41: Bow Spring | E41: ='DECK TALLY'!B17 -> 12 | F41: =VLOOKUP(E41,'DECK TALLY'!$B$6:$C$316,2,FALSE) -> 33.94 | G41: =F41-($H$12/12) -> 33.5345 | H41: IN | I41: =IF(H41="IN",I40+G41,I40) -> 586.0255 | J41: =IF(I41="","",$M$10-I41) -> 20768.975
A42: Vam 21 HT NX | C42: 2 | D42: Bow Spring | E42: ='DECK TALLY'!B18 -> 13 | F42: =VLOOKUP(E42,'DECK TALLY'!$B$6:$C$316,2,FALSE) -> 33.85 | G42: =F42-($H$12/12) -> 33.4445 | H42: IN | I42: =IF(H42="IN",I41+G42,I41) -> 619.47 | J42: =IF(I42="","",$M$10-I42) -> 20735.53
A43: Vam 21 HT NX | C43: 2 | D43: Bow Spring | E43: ='DECK TALLY'!B19 -> 14 | F43: =VLOOKUP(E43,'DECK TALLY'!$B$6:$C$316,2,FALSE) -> 33.55 | G43: =F43-($H$12/12) -> 33.1445 | H43: IN | I43: =IF(H43="IN",I42+G43,I42) -> 652.6145 | J43: =IF(I43="","",$M$10-I43) -> 20702.386
...

Sheet Sheet1
A1: Run Number | B1: Depth of Top of Joint
A2: 1 | B2: 21154.679
A3: 20ft Pup Jt | B3: 21134.884
A4: 2 | B4: 21101.35
A5: 3 | B5: 21067.815
A6: 4 | B6: 21034.321
A7: 5 | B7: 21000.836
A8: 6 | B8: 20967.721
A9: 7 | B9: 20935.677
A10: 8 | B10: 20902.312
A11: 9 | B11: 20869.318
A12: 10 | B12: 20835.893
A13: 11 | B13: 20802.509
A14: 12 | B14: 20768.975
A15: 13 | B15: 20735.53
... A66: 64 | B66: 19110.289
A67: 20ft Pup Jt | B67: 19090.475
A68: 65 | B68: 19056.921
A69: 66 | B69: 19023.386
A70: 67 | B70: 18989.852
A71: 68 | B71: 18956.317
A72: 69 | B72: 18922.783
A73: 70 | B73: 18889.428
A74: 71 | B74: 18856.264
A75: 72 | B75: 18822.869
A76: 73 | B76: 18789.694
A77: 74 | B77: 18756.16
A78: 75 | B78: 18722.895
A79: 76 | B79: 18689.801
... A130: 127 | B130: 16989.921
A131: 10ft Pup Jt | B131: 16980.107
A132: 128 | B132: 16946.572
A133: 129 | B133: 16913.158
A134: 130 | B134: 16881.563
A135: 131 | B135: 16848.009
A136: 132 | B136: 16814.454
A137: 133 | B137: 16780.9
A138: 134 | B138: 16747.345
A139: 135 | B139: 16713.801
A140: 136 | B140: 16680.676
...

Sheet DECK TALLY
A1: hoe assemblies
B2: DECK TALLY NFQ 22-5
B4: 7" 29# VAM21HT CSG JOINTS ( 2 x Centralizers) | F4: 7" 29# VAM21HT PUP JOINTS | J4: Primary Shoe Track Assemblies | L4: NFQ 22-9
B5: Joint Num. | C5: Length (ft) | D5: Note | F5: Joint No | G5: Length (ft) | H5: Note | J5: Items | K5: Length (ft)
A6: 1 | B6: 1 | C6: 33.75 | D6: 7" 29# Vam 21 HT-NX | E6: Pip Tag # 5 | F6: P 1 | G6: 10.22 | H6: Vam 21 HT | J6: Float Shoe, DV Eccentric | K6: 3.37 | L6: QELNG-7in-FS-171-NFE
A7: =A6+1 -> 2 | B7: =B6+1 -> 2 | C7: 33.94 | D7: 7" 29# Vam 21 HT-NX | F7: P 2 | G7: 10.22 | H7: Vam 21 HT | J7: Shoe Joint | K7: 37.2
A8: =A7+1 -> 3 | B8: =B7+1 -> 3 | C8: 33.94 | D8: 7" 29# Vam 21 HT-NX | E8: Pip Tag # 3 | F8: P 3 | G8: 20.22 | H8: Vam 21 HT
A9: =A8+1 -> 4 | B9: =B8+1 -> 4 | C9: 33.9 | D9: 7" 29# Vam 21 HT-NX | E9: Pip Tag # 4 | F9: P 4 | G9: 20.24 | H9: Vam 21 HT | J9: Bttm FC Pup Joint | K9: 20.26 | L9: QELNG-7in-FC-171-NFE
A10: =A9+1 -> 5 | B10: =B9+1 -> 5 | C10: 33.89 | D10: 7" 29# Vam 21 HT-NX | E10: Pip Tag # 2 | F10: P 5 | G10: 10.22 | H10: Vam 21 HT | J10: Float Collar - DV | K10: 2.91
A11: =A10+1 -> 6 | B11: =B10+1 -> 6 | C11: 33.52 | D11: 7" 29# Vam 21 HT-NX | E11: Pip Tag # 7 | F11: P 6 | G11: 20.2 | H11: Vam 21 HT | J11: Top FC Pup Joint | K11: 19.9
A12: =A11+1 -> 7 | B12: =B11+1 -> 7 | C12: 32.45 | D12: 7" 29# Vam 21 HT-NX | F12: P 7 | G12: 20.2 | H12: Vam 21 HT
A13: =A12+1 -> 8 | B13: =B12+1 -> 8 | C13: 33.77 | D13: 7" 29# Vam 21 HT-NX | J13: Bttm Pup Joint | K13: 18.35 | L13: QELNG-7in-LC-172-NFE-VT HC
A14: =A13+1 -> 9 | B14: =B13+1 -> 9 | C14: 33.4 | D14: 7" 29# Vam 21 HT-NX | J14: LFC Landing Collar | K14: 4.41
A15: =A14+1 -> 10 | B15: =B14+1 -> 10 | C15: 33.83 | D15: 7" 29# Vam 21 HT-NX | J15: Top Pup Joint | K15: 17.47
A16: =A15+1 -> 11 | B16: =B15+1 -> 11 | C16: 33.79 | D16: 7" 29# Vam 21 HT-NX | J16: Top Crossover | K16: 5.48
A17: =A16+1 -> 12 | B17: =B16+1 -> 12 | C17: 33.94 | D17: 7" 29# Vam 21 HT-NX
A18: =A17+1 -> 13 | B18: =B17+1 -> 13 | C18: 33.85 | D18: 7" 29# Vam 21 HT-NX | J18: Full length joint with Vam Top HC Box x Pin | K18: 33.35 | L18: QELNG-7in-XO-32NFE
A19: =A18+1 -> 14 | B19: =B18+1 -> 14 | C19: 33.55 | D19: 7" 29# Vam 21 HT-NX | J19: X' over with Vam Top HC pin x Vam 21 HT box | K19: 5.35
A20: =A19+1 -> 15 | B20: =B19+1 -> 15 | C20: 33.58 | D20: 7" 29# Vam 21 HT-NX | J20: Full length joint with Vam 21HT-NX Box x Pin | K20: 33.97 | L20: QELNG-7in-XO-33 NFE
A21: =A20+1 -> 16 | B21: =B20+1 -> 16 | C21: 33.71 | D21: 7" 29# Vam 21 HT-NX | J21: X' over with VAM 21 HT pin x TSH Wedge 563 box | K21: 4.03
A22: =A21+1 -> 17 | B22: =B21+1 -> 17 | C22: 33.94 | D22: 7" 29# Vam 21 HT-NX
A23: =A22+1 -> 18 | B23: =B22+1 -> 18 | C23: 33.96 | D23: 7" 29# Vam 21 HT-NX
A24: =A23+1 -> 19 | B24: =B23+1 -> 19 | C24: 33.95 | D24: 7" 29# Vam 21 HT-NX | J24: Back up Shoe Track Assemblies
A25: =A24+1 -> 20 | B25: =B24+1 -> 20 | C25: 33.79 | D25: 7" 29# Vam 21 HT-NX | J25: Items | K25: Length (ft)
A26: =A25+1 -> 21 | B26: =B25+1 -> 21 | C26: 33.94 | D26: 7" 29# Vam 21 HT-NX | J26: Float Shoe, DV Eccentric | L26: QELNG-7in-FS -174 -NFE
A27: =A26+1 -> 22 | B27: =B26+1 -> 22 | C27: 33.95 | D27: 7" 29# Vam 21 HT-NX | J27: Shoe Joint
A28: =A27+1 -> 23 | B28: =B27+1 -> 23 | C28: 33.72 | D28: 7" 29# Vam 21 HT-NX
A29: =A28+1 -> 24 | B29: =B28+1 -> 24 | C29: 33.67 | D29: 7" 29# Vam 21 HT-NX | J29: Bttm FC Pup Joint | L29: QELNG-7in-FC -174 -NFE
A30: =A29+1 -> 25 | B30: =B29+1 -> 25 | C30: 33.95 | D30: 7" 29# Vam 21 HT-NX | J30: Float Collar - DV
A31: =A30+1 -> 26 | B31: =B30+1 -> 26 | C31: 33.9 | D31: 7" 29# Vam 21 HT-NX | J31: Top FC Pup Joint
A32: =A31+1 -> 27 | B32: =B31+1 -> 27 | C32: 33.9 | D32: 7" 29# Vam 21 HT-NX
A33: =A32+1 -> 28 | B33: =B32+1 -> 28 | C33: 33.9 | D33: 7" 29# Vam 21 HT-NX | J33: Bttm Pup Joint | L33: QELNG-7in-LC-174-NFE VTHC
A34: =A33+1 -> 29 | B34: =B33+1 -> 29 | C34: 33.72 | D34: 7" 29# Vam 21 HT-NX | J34: LFC Landing Collar
A35: =A34+1 -> 30 | B35: =B34+1 -> 30 | C35: 33.85 | D35: 7" 29# Vam 21 HT-NX | J35: Top Pup Joint
A36: =A35+1 -> 31 | B36: =B35+1 -> 31 | C36: 33.76 | D36: 7" 29# Vam 21 HT-NX | J36: Top Crossover
A37: =A36+1 -> 32 | B37: =B36+1 -> 32 | C37: 33.94 | D37: 7" 29# Vam 21 HT-NX
A38: =A37+1 -> 33 | B38: =B37+1 -> 33 | C38: 33.36 | D38: 7" 29# Vam 21 HT-NX
A39: =A38+1 -> 34 | B39: =B38+1 -> 34 | C39: 33.94 | D39: 7" 29# Vam 21 HT-NX
A40: =A39+1 -> 35 | B40: =B39+1 -> 35 | C40: 32.4 | D40: 7" 29# Vam 21 HT-NX
A41: =A40+1 -> 36 | B41: =B40+1 -> 36 | C41: 33.93 | D41: 7" 29# Vam 21 HT-NX
...

Sheet Sheet2
