Workbook
Name ___add1: '[1]Well-20'!#REF!
Name ___add2: '[1]Well-20'!#REF!
Name ___add3: '[1]Well-20'!#REF!
Name ___add4: '[1]Well-20'!#REF!
Name ___add5: '[1]Well-20'!#REF!
Name ___add6: '[1]Well-20'!#REF!
Name ___add7: '[1]Well-20'!#REF!
Name ___add8: '[1]Well-20'!#REF!
Name ___add9: '[1]Well-20'!#REF!
Name ___cem20: '[1]Well-20'!#REF!
Name ___cem30: '[1]Well-20'!#REF!
Name ___tot13: #REF!
Name ___tot30: #REF!
Name ___tot7: #REF!
Name ___tot9: #REF!
Name ___xs20: #REF!
Name __add1: '[1]Well-20'!#REF!
Name __add2: '[1]Well-20'!#REF!
Name __add3: '[1]Well-20'!#REF!
Name __add4: '[1]Well-20'!#REF!
Name __add5: '[1]Well-20'!#REF!
Name __add6: '[1]Well-20'!#REF!
Name __add7: '[1]Well-20'!#REF!
Name __add8: '[1]Well-20'!#REF!
Name __add9: '[1]Well-20'!#REF!
Name __cem20: '[1]Well-20'!#REF!
Name __cem30: '[1]Well-20'!#REF!
Name __NFQ6: #REF!
Name __tot13: #REF!
Name __tot30: #REF!
Name __tot7: #REF!
Name __tot9: #REF!
Name __xs20: #REF!
Name _58_D124_bwoc: NA()
Name _58_D124_bwoc_1: NA()
Name _58_XE825_bwoc: NA()
Name _58_XE825_bwoc_1: NA()
Name _add1: NA()
Name _add1_1: NA()
Name _add2: NA()
Name _add2_1: NA()
Name _add3: NA()
Name _add3_1: NA()
Name _add4: NA()
Name _add4_1: NA()
Name _add5: NA()
Name _add5_1: NA()
Name _add6: NA()
Name _add6_1: NA()
Name _add7: NA()
Name _add7_1: NA()
Name _add8: NA()
Name _add8_1: NA()
Name _add9: NA()
Name _add9_1: NA()
Name _cem20: NA()
Name _cem20_1: NA()
Name _cem30: NA()
Name _cem30_1: NA()
Name _Fill: NA()

Sheet xxxxxx

Sheet Liner Tally NFQ22-2
I2: Baker Hughes | L2: Final As Run
I3: 7" LINER TALLY
D5: Tension: | E5: 929 | G5: Well: | H5: NFQ22-2 | K5: Date: | L5: 44369
D6: Burst: | E6: 11540 | G6: Rig: | H6: Lovanda | K6: QE LNG Representative: | L6: Logan /Graham / Faouzi
D7: Collapse: | E7: 8530 | G7: Liner Run # : | H7: 1 | K7: Baker Representative: | L7: Nurlan / El-Sayaad
D8: Casing Size: | E8: 7 | G8: Block Weight: | H8: 85 | K8: 7" Shoe Depth: | L8: =L9-9.42 -> 19728.58
D9: Weight: | E9: 29 | G9: Mud Weight: | H9: 12.3 | K9: Total Depth: | L9: 19738 | Q9: 19818
D10: Grade: | E10: SM2535-110 | G10: Bouyancy Factor: | H10: =(65.45-H9)/65.45 -> 0.81207028 | K10: Rat Hole: | L10: 10
D11: Make Up Loss: | E11: 4.866 | G11: Casing ID: | H11: 6.25 | K11: 7" Liner Top: | L11: =J336 -> 9869.244
D12: Drift: | E12: 6.059 | G12: Connection: | H12: VAM 21 HT NX | K12: 9-5/8" Shoe: | L12: 10121.55
D13: Centralizers: | E13: =SUM(C17:C317) -> 578 | G13: Centralizer Type: | H13: Red-X Bow Spring | K13: 9-5/8" x 10-3/4" Crossover: | L13: 1350.24
B15: JOINTS | C15: CENTRALIZERS/DESC | E15: JOINT | F15: JOINT | G15: EFFECTIVE | H15: JOINT | I15: TOTAL | J15: DEPTH OF | K15: EST STRG | L15: COMMENTS
B16: RUN | C16: NO | D16: TYPE | E16: NUMBER | F16: LENGTH | G16: LENGTH | H16: IN/OUT | I16: LENGTH | J16: TOP OF JT | K16: WEIGHT
B17: QELNG-7in-FS-177-NFE | C17: - | D17: Float Shoe - DV | F17: 3.37 | G17: =F17 -> 3.37 | H17: =IF(F17="","OUT","IN") -> IN | I17: =G17 -> 3.37 | J17: =L8-G17 -> 19725.21 | K17: =$H$8+(I17*$E$9*$H$10/1000) -> 85.079364 | L17: DV Float Shoe: SN:112201-112225-10 PN: H100950451GRG1
C18: 2 | D18: Shoe Joint | F18: 36.2 | G18: =F18 -> 36.2 | H18: =IF(F18="","OUT","IN") -> IN | I18: =IF(H18="IN",I17+G18,I17) -> 39.57 | J18: =IF(I18="","",$L$8-I18) -> 19689.01 | K18: =$H$8+(I18*$E$9*$H$10/1000) -> 85.931875
B19: QELNG-7in-FC-177-NFE | C19: 1 | D19: FC Pup Joint | F19: 20.24 | G19: =F19-(4.05/12) -> 19.9025 | H19: =IF(F19="","OUT","IN") -> IN | I19: =IF(H19="IN",I18+G19,I18) -> 59.4725 | J19: =IF(I19="","",$L$8-I19) -> 19669.108 | K19: =$H$8+(I19*$E$9*$H$10/1000) -> 86.40058 | L19: DV Float Collar: PN: H101890295GRG1 SN: 112200-112222-11
C20: - | D20: Float Collar - DV | F20: 2.91 | G20: =F20 -> 2.91 | H20: =IF(F20="","OUT","IN") -> IN | I20: =IF(H20="IN",I19+G20,I19) -> 62.3825 | J20: =IF(I20="","",$L$8-I20) -> 19666.198 | K20: =$H$8+(I20*$E$9*$H$10/1000) -> 86.46911
C21: 1 | D21: FC Pup Joint | F21: 19.91 | G21: =F21 -> 19.91 | H21: =IF(F21="","OUT","IN") -> IN | I21: =IF(H21="IN",I20+G21,I20) -> 82.2925 | J21: =IF(I21="","",$L$8-I21) -> 19646.288 | K21: =$H$8+(I21*$E$9*$H$10/1000) -> 86.937992
B22: QELNG-7in-LC-182-NFE-VT-21 | C22: 1 | D22: Pup Joint | F22: 20.24 | G22: =F22-(4.05/12) -> 19.9025 | H22: =IF(F22="","OUT","IN") -> IN | I22: =IF(H22="IN",I21+G22,I21) -> 102.195 | J22: =IF(I22="","",$L$8-I22) -> 19626.385 | K22: =$H$8+(I22*$E$9*$H$10/1000) -> 87.406696 | L22: LFC Landing Collar: PN: H274120438GRG1 SN:108656272-03
C23: - | D23: LFC Landing Collar | F23: 4.41 | G23: =F23 -> 4.41 | H23: =IF(F23="","OUT","IN") -> IN | I23: =IF(H23="IN",I22+G23,I22) -> 106.605 | J23: =IF(I23="","",$L$8-I23) -> 19621.975 | K23: =$H$8+(I23*$E$9*$H$10/1000) -> 87.510552
C24: 1 | D24: Pup Joint | F24: 19.91 | G24: =F24 -> 19.91 | H24: =IF(F24="","OUT","IN") -> IN | I24: =IF(H24="IN",I23+G24,I23) -> 126.515 | J24: =IF(I24="","",$L$8-I24) -> 19602.065 | K24: =$H$8+(I24*$E$9*$H$10/1000) -> 87.979433
D25: X-Over TSH x VAM | F25: 3.89 | G25: =F25 -> 3.89 | H25: =IF(F25="","OUT","IN") -> IN | I25: =IF(H25="IN",I24+G25,I24) -> 130.405 | J25: =IF(I25="","",$L$8-I25) -> 19598.175 | K25: =$H$8+(I25*$E$9*$H$10/1000) -> 88.071043
B26: 1 | C26: 2 | D26: 7" 29# CSG | E26: 1 | F26: =VLOOKUP(E26,'Deck Tally'!$B$5:$C$274,2,0) -> 33.955 | G26: =F26-($E$11/12) -> 33.5495 | H26: IN | I26: =IF(H26="IN",I25+G26,I25) -> 163.9545 | J26: =IF(I26="","",$L$8-I26) -> 19564.626 | K26: =$H$8+(I26*$E$9*$H$10/1000) -> 88.861135 | L26: **BakerLok first 3ea connections
B27: =B26+1 -> 2 | C27: 2 | D27: 7" 29# CSG | E27: 2 | F27: =VLOOKUP(E27,'Deck Tally'!$B$5:$C$274,2,0) -> 33.94 | G27: =F27-($E$11/12) -> 33.5345 | H27: IN | I27: =IF(H27="IN",I26+G27,I26) -> 197.489 | J27: =IF(I27="","",$L$8-I27) -> 19531.091 | K27: =$H$8+(I27*$E$9*$H$10/1000) -> 89.650873
B28: =B27+1 -> 3 | C28: 2 | D28: 7" 29# CSG | E28: 3 | F28: =VLOOKUP(E28,'Deck Tally'!$B$5:$C$274,2,0) -> 32.78 | G28: =F28-($E$11/12) -> 32.3745 | H28: IN | I28: =IF(H28="IN",I27+G28,I27) -> 229.8635 | J28: =IF(I28="","",$L$8-I28) -> 19498.717 | K28: =$H$8+(I28*$E$9*$H$10/1000) -> 90.413294
B29: =B28+1 -> 4 | C29: 2 | D29: 7" 29# CSG | E29: 4 | F29: =VLOOKUP(E29,'Deck Tally'!$B$5:$C$274,2,0) -> 33.945 | G29: =F29-($E$11/12) -> 33.5395 | H29: IN | I29: =IF(H29="IN",I28+G29,I28) -> 263.403 | J29: =IF(I29="","",$L$8-I29) -> 19465.177 | K29: =$H$8+(I29*$E$9*$H$10/1000) -> 91.203151
B30: =B29+1 -> 5 | C30: 2 | D30: 7" 29# CSG | E30: 5 | F30: =VLOOKUP(E30,'Deck Tally'!$B$5:$C$274,2,0) -> 33.675 | G30: =F30-($E$11/12) -> 33.2695 | H30: IN | I30: =IF(H30="IN",I29+G30,I29) -> 296.6725 | J30: =IF(I30="","",$L$8-I30) -> 19431.908 | K30: =$H$8+(I30*$E$9*$H$10/1000) -> 91.986649
C31: 1 | D31: 20 ft PUP | E31: PJ 1 | F31: 20.22 | G31: =F31-($E$11/12) -> 19.8145 | H31: IN | I31: =IF(H31="IN",I30+G31,I30) -> 316.487 | J31: =IF(I31="","",$L$8-I31) -> 19412.093 | K31: =$H$8+(I31*$E$9*$H$10/1000) -> 92.453281 | L31: Planned PIP @ 19420 ft
B32: =B30+1 -> 6 | C32: 2 | D32: 7" 29# CSG | E32: 6 | F32: =VLOOKUP(E32,'Deck Tally'!$B$5:$C$274,2,0) -> 33.05 | G32: =F32-($E$11/12) -> 32.6445 | H32: IN | I32: =IF(H32="IN",I31+G32,I31) -> 349.1315 | J32: =IF(I32="","",$L$8-I32) -> 19379.449 | K32: =$H$8+(I32*$E$9*$H$10/1000) -> 93.22206 | L32: INSTALL PIP TAG #1 ON JT #6 | O32: =19420-M33 -> 11.907 | P32: ft. Difference
B33: =B32+1 -> 7 | C33: 1 | D33: 7" 29# CSG | E33: 7 | F33: =VLOOKUP(E33,'Deck Tally'!$B$5:$C$274,2,0) -> 33.94 | G33: =F33-($E$11/12) -> 33.5345 | H33: IN | I33: =IF(H33="IN",I32+G33,I32) -> 382.666 | J33: =IF(I33="","",$L$8-I33) -> 19345.914 | K33: =$H$8+(I33*$E$9*$H$10/1000) -> 94.011799 | L33: 4 ft above pin @ | M33: =J31-4 -> 19408.093
B34: =B33+1 -> 8 | C34: 2 | D34: 7" 29# CSG | E34: 8 | F34: =VLOOKUP(E34,'Deck Tally'!$B$5:$C$274,2,0) -> 33.875 | G34: =F34-($E$11/12) -> 33.4695 | H34: IN | I34: =IF(H34="IN",I33+G34,I33) -> 416.1355 | J34: =IF(I34="","",$L$8-I34) -> 19312.445 | K34: =$H$8+(I34*$E$9*$H$10/1000) -> 94.800007 | L34: Remove Bottom Centralizer
B35: =B34+1 -> 9 | C35: 2 | D35: 7" 29# CSG | E35: 9 | F35: =VLOOKUP(E35,'Deck Tally'!$B$5:$C$274,2,0) -> 33.94 | G35: =F35-($E$11/12) -> 33.5345 | H35: IN | I35: =IF(H35="IN",I34+G35,I34) -> 449.67 | J35: =IF(I35="","",$L$8-I35) -> 19278.91 | K35: =$H$8+(I35*$E$9*$H$10/1000) -> 95.589746
B36: =B35+1 -> 10 | C36: 2 | D36: 7" 29# CSG | E36: 10 | F36: =VLOOKUP(E36,'Deck Tally'!$B$5:$C$274,2,0) -> 33.955 | G36: =F36-($E$11/12) -> 33.5495 | H36: IN | I36: =IF(H36="IN",I35+G36,I35) -> 483.2195 | J36: =IF(I36="","",$L$8-I36) -> 19245.361 | K36: =$H$8+(I36*$E$9*$H$10/1000) -> 96.379838
B37: =B36+1 -> 11 | C37: 2 | D37: 7" 29# CSG | E37: 11 | F37: =VLOOKUP(E37,'Deck Tally'!$B$5:$C$274,2,0) -> 32.79 | G37: =F37-($E$11/12) -> 32.3845 | H37: IN | I37: =IF(H37="IN",I36+G37,I36) -> 515.604 | J37: =IF(I37="","",$L$8-I37) -> 19212.976 | K37: =$H$8+(I37*$E$9*$H$10/1000) -> 97.142494
B38: =B37+1 -> 12 | C38: 2 | D38: 7" 29# CSG | E38: 12 | F38: =VLOOKUP(E38,'Deck Tally'!$B$5:$C$274,2,0) -> 33.94 | G38: =F38-($E$11/12) -> 33.5345 | H38: IN | I38: =IF(H38="IN",I37+G38,I37) -> 549.1385 | J38: =IF(I38="","",$L$8-I38) -> 19179.442 | K38: =$H$8+(I38*$E$9*$H$10/1000) -> 97.932233
B39: =B38+1 -> 13 | C39: 2 | D39: 7" 29# CSG | E39: 13 | F39: =VLOOKUP(E39,'Deck Tally'!$B$5:$C$274,2,0) -> 33.945 | G39: =F39-($E$11/12) -> 33.5395 | H39: IN | I39: =IF(H39="IN",I38+G39,I38) -> 582.678 | J39: =IF(I39="","",$L$8-I39) -> 19145.902 | K39: =$H$8+(I39*$E$9*$H$10/1000) -> 98.722089
B40: =B39+1 -> 14 | C40: 2 | D40: 7" 29# CSG | E40: 14 | F40: =VLOOKUP(E40,'Deck Tally'!$B$5:$C$274,2,0) -> 33.945 | G40: =F40-($E$11/12) -> 33.5395 | H40: IN | I40: =IF(H40="IN",I39+G40,I39) -> 616.2175 | J40: =IF(I40="","",$L$8-I40) -> 19112.363 | K40: =$H$8+(I40*$E$9*$H$10/1000) -> 99.511946
B41: =B40+1 -> 15 | C41: 2 | D41: 7" 29# CSG | E41: 15 | F41: =VLOOKUP(E41,'Deck Tally'!$B$5:$C$274,2,0) -> 33.945 | G41: =F41-($E$11/12) -> 33.5395 | H41: IN | I41: =IF(H41="IN",I40+G41,I40) -> 649.757 | J41: =IF(I41="","",$L$8-I41) -> 19078.823 | K41: =$H$8+(I41*$E$9*$H$10/1000) -> 100.3018
B42: =B41+1 -> 16 | C42: 2 | D42: 7" 29# CSG | E42: 16 | F42: =VLOOKUP(E42,'Deck Tally'!$B$5:$C$274,2,0) -> 33.94 | G42: =F42-($E$11/12) -> 33.5345 | H42: IN | I42: =IF(H42="IN",I41+G42,I41) -> 683.2915 | J42: =IF(I42="","",$L$8-I42) -> 19045.289 | K42: =$H$8+(I42*$E$9*$H$10/1000) -> 101.09154
B43: =B42+1 -> 17 | C43: 2 | D43: 7" 29# CSG | E43: 17 | F43: =VLOOKUP(E43,'Deck Tally'!$B$5:$C$274,2,0) -> 33.955 | G43: =F43-($E$11/12) -> 33.5495 | H43: IN | I43: =IF(H43="IN",I42+G43,I42) -> 716.841 | J43: =IF(I43="","",$L$8-I43) -> 19011.739 | K43: =$H$8+(I43*$E$9*$H$10/1000) -> 101.88163
...

Sheet Deck Tally
B2: 7" 29# Deck Tally | F2: 7" 29# Pup Jnt'S
B4: Deck # | C4: Length (ft) | D4: Location | F4: Deck # | G4: Length (ft) | H4: Location
A5: 1 | B5: 1 | C5: 33.955 | F5: PJ 1 | G5: 20.22 | H5: Used
A6: 2 | B6: 2 | C6: 33.94 | F6: PJ 2 | G6: 20.23 | H6: Used
A7: 3 | B7: 3 | C7: 32.78 | F7: PJ 3 | G7: 20.22 | H7: Used
A8: 4 | B8: 4 | C8: 33.945 | F8: PJ 4 | G8: 20.23
A9: 5 | B9: 5 | C9: 33.675 | F9: PJ 5 | G9: 10.21 | H9: Used
A10: 6 | B10: 6 | C10: 33.05 | F10: PJ 6 | G10: 10.21 | H10: Used
A11: 7 | B11: 7 | C11: 33.94 | F11: PJ 7 | G11: 10.22 | H11: Used
A12: 8 | B12: 8 | C12: 33.875
A13: 9 | B13: 9 | C13: 33.94
A14: 10 | B14: 10 | C14: 33.955
A15: 11 | B15: 11 | C15: 32.79
A16: 12 | B16: 12 | C16: 33.94
A17: 13 | B17: 13 | C17: 33.945
A18: 14 | B18: 14 | C18: 33.945
A19: 15 | B19: 15 | C19: 33.945
A20: 16 | B20: 16 | C20: 33.94
A21: 17 | B21: 17 | C21: 33.955
A22: 18 | B22: 18 | C22: 33.945
A23: 19 | B23: 19 | C23: 33.935
... A301: 297 | B301: 297 | C301: 33.925
A302: 298 | B302: 298
A303: 299 | B303: 299
A304: 300 | B304: 300
A305: 301 | B305: 301
A306: 302 | B306: 302
A307: 303 | B307: 303
A308: 304 | B308: 304
A309: 305 | B309: 305
A310: 306 | B310: 306
A311: 307 | B311: 307
A312: 308 | B312: 308
A313: 309 | B313: 309
... A319: 315 | B319: 315
