Workbook
Name \A: #REF!
Name \A: #REF!
Name \A: #REF!
Name \B: #REF!
Name \B: #REF!
Name \C: #REF!
Name \C: #REF!
Name \C: #REF!
Name \D: #REF!
Name \D: #REF!
Name \D: #REF!
Name \E: #REF!
Name \E: #REF!
Name \E: #REF!
Name \f: #REF!
Name \f: #REF!
Name \g: #REF!
Name \g: #REF!
Name \h: #REF!
Name \h: #REF!
Name \I: #REF!
Name \I: #REF!
Name \I: #REF!
Name \J: #REF!
Name \J: #REF!
Name \J: #REF!
Name \L: #REF!
Name \L: #REF!
Name \L: #REF!
Name \N: #REF!
Name \N: #REF!
Name \N: #REF!
Name \q: #REF!
Name \q: #REF!
Name \r: #REF!
Name \r: #REF!
Name \S: #REF!
Name \S: #REF!
Name \V: #REF!
Name \V: #REF!
Name \X: #REF!
Name \X: #REF!
Name \X: #REF!
Name \Z: #REF!
Name \Z: #REF!
Name \Z: #REF!
Name __BHR1: #REF!
Name __BHR1: #REF!
Name __Col1: #REF!
Name __Col1: #REF!
Name __Col10: #REF!
Name __Col10: #REF!
Name __Col11: #REF!
Name __Col11: #REF!
Name __Col12: #REF!
Name __Col12: #REF!
Name __Col13: #REF!
Name __Col13: #REF!
Name __Col14: #REF!
Name __Col14: #REF!

Sheet RIH-DRAFT
B1: UPPER COMPLETION SERVICES
F2: DRAFT TALLY REV : 03
C3: CUSTOMER : | D3: Sapura OMV
C4: WELL # : | D4: Jerun A-4 | G4: SPECIFICATION: [MEASURED JOINTS]
C5: DATE : | D5: =TODAY() -> 46047 | F5: DESCRIPTION | G5: SIZE GRADE WEIGHT THREAD DEPTH m | K5: L/OUT | L5: RIH | M5: BAL | N5: OD (in) | O5: ID (in) | P5: Drift ID
C6: RIG : | D6: Gunnlod Jack Up Rig | F6: PROD. CASING | G6: 9-5/8" | H6: L80 | I6: '47# VAM 21 1732.62 | K6: - | N6: 10.42 / 9.625 | O6: 8.681 | P6: 8.525 | T6: LINER | U6: 6-5/8" | V6: 24ppf | W6: L80-13Cr | X6: 5.921 | Y6: 5.796 | Z6: VAM21-HT
C7: CUSTOMER REPS : | D7: Jamel Abd Rahman (DSV) | F7: PROD. CASING | G7: 10-3/4" | H7: L80 | I7: '55.5# VAM 21 310.15 | K7: - | N7: 11.626 / 10.75 | O7: 9.76 | P7: 9.235 | T7: TUBING | U7: 7" | V7: 23ppf | W7: L80-13Cr | X7: 6.366 | Y7: 6.241 | Z7: JFE LION
D8: Syahdimin Rashidi (NDSV) | F8: SLOTTED LINER | G8: 7" | H8: L80-13Cr | I8: '26# VAM TOP 2020 | K8: 18 | L8: 17 | M8: =K8-L8 -> 1 | N8: 7.565 / 7.00 | O8: 6.276 | P8: 6.151 | T8: 9-5/8" | U8: 47ppf | V8: L80 | W8: 8.681 | X8: 8.525 | Y8: VAM TOP
F9: LINER BLANK | G9: 7" | H9: L80-13Cr | I9: '26# VAM TOP '- | K9: 18 | L9: 7 | M9: =K9-L9 -> 11 | O9: 6.276
D10: Mohd Zainudi Shah (CSV) | F10: TUBING | G10: 7" | H10: HP2-13Cr-95 | I10: '29# JFE LION (TBC) | K10: 153 | L10: 132 | M10: =K10-L10 -> 21 | N10: 7.752 / 7.00 | O10: 6.184 | P10: 6.059
D11: Jawan Undom (NCSV)
C13: HALLIBURTON REPS : | D13: Hitla Baring, Khoa Nguyen | G13: M/UP LOSS (in / m) | I13: MINIMUM (ft-lb) OPTIMUM (ft-lb) MAXIMUM TORQUE (ft-lb)
D14: Natalie Chu | F14: LINER (Vam Top) | G14: 4.775 | H14: =(G14/12)/3.281 -> 0.12127908 | I14: 7470 8300 9130
D15: Keith Armstrong, Rozaidi Tek | F15: TUBING (JFE Lion) | G15: 4.85 | H15: =(G15/12)/3.281 -> 0.12318399 | I15: 15080 16300 17520
C16: COMPLETION TYPE: | D16: Single Gas Producer
C17: COMPLETION FLUID: | D17: Inhibited Sea water, 8.5 ppg
C18: PACKER FLUID : | D18: Inhibited Sea water, 8.5 ppg
C19: CASING FLUID : | D19: Inhibited Sea water, 8.5 ppg
B21: Assy | C21: Item Description | D21: Jt No. | E21: OD | F21: ID | G21: Length | H21: Final Depth | I21: RIH Depth | J21: CCP / CL | K21: Notes | O21: TBG | P21: CHECK
B22: No. | C22: SINGLE STRING | E22: (Inch) | F22: (Inch) | G22: (m MDDF) | H22: (m MDDF) | I22: (m MDDF) | O22: RIH
C24: MAX DEVIATION : 36.3 Deg @ 978.15m MDDF
C25: 10-3/4" x 9-5/8" Casing Shoe Depth | H25: 1732.62
C26: 10-3/4" x 9-5/8" XO Depth | H26: 310.15
C28: NOTE: | T28: =IF(L28>0,P28+L28,"")
C29: All length have been accounted for make up loss
P30: =IF(H30>0,H30+I30,"") | S30: =IF(F30>0,G30+F30,"")
C31: Top of Baker Liner Hanger | H31: 1681.767
P32: =IF(H32>0,H32+I32,"")
C33: E.O.T | H33: =H34+G34 -> 1684.1074 | P33: =IF(H33>0,H33+I33,"") -> 1684.1074
H34: =H35+G35 -> 1684.1074 | P34: =IF(H34>0,H34+I34,"") -> 1684.1074
C35: =H40-1682.6 -> -1.4425703 | H35: =H36+G36 -> 1684.1074 | P35: =IF(H35>0,H35+I35,"") -> 1684.1074
C36: Proposed depth : 1682.6 m | H36: =H37+G37 -> 1684.1074 | I36: 0 | O36: 0 | P36: =IF(H36>0,H36+I36,"") -> 1684.1074
B37: Assy #1 Baker Tie Back Assy | C37: Bottom Bullet Seal Packing to end of Half Mule Shoe | E37: 7.25 | F37: 6.063 | G37: 1.79 | H37: =H38+G38 -> 1682.3174 | I37: =I36+G37 -> 1.79 | O37: =IF(D37>0,O36+1,O36) -> 0 | P37: =IF(H37>0,H37+I37,"") -> 1684.1074 | R37: nata
C38: Middle Seal to Bottom Bullet Seal Packing | E38: 7.438 | F38: 6.063 | G38: 0.3 | H38: =H39+G39 -> 1682.0174 | I38: =I37+G38 -> 2.09 | O38: =IF(D38>0,O37+1,O37) -> 0 | P38: =IF(H38>0,H38+I38,"") -> 1684.1074
C39: Top Seal to Middle Bullet Seal Packing | E39: 7.438 | F39: 6.063 | G39: 0.3 | H39: =H40+G40 -> 1681.7174 | I39: =I38+G39 -> 2.39 | O39: =IF(D39>0,O38+1,O38) -> 0 | P39: =IF(H39>0,H39+I39,"") -> 1684.1074
C40: NO - GO Locator to Top Bullet Seal Packing | E40: 7.438 | F40: 6.063 | G40: 0.56 | H40: =H31-(2/3.281) -> 1681.1574 | I40: =I39+G40 -> 2.95 | K40: *Note: Depth based on 2ft pick up-space out. | O40: =IF(D40>0,O39+1,O39) -> 0 | P40: =IF(H40>0,H40+I40,"") -> 1684.1074
C41: Coupling 7'' 29ppf JFELion B x B To NO-GO LOCATOR | E41: 8.25 | F41: 6.125 | G41: 0.34 | H41: =H40-G41 -> 1680.8174 | I41: =I40+G41 -> 3.29 | O41: =IF(D41>0,O40+1,O40) -> 0 | P41: =IF(H41>0,H41+I41,"") -> 1684.1074
C42: 6ft Pup Joint 7'' 29ppf 13CR 95KSI JFELion BOX X PIN | E42: 7.875 | F42: 6.125 | G42: 1.765 | H42: =H41-G42 -> 1679.0524 | I42: =I41+G42 -> 5.055 | O42: =IF(D42>0,O41+1,O41) -> 0 | P42: =IF(H42>0,H42+I42,"") -> 1684.1074
H43: =H42-G43 -> 1679.0524 | I43: =I42+G43 -> 5.055 | O43: =IF(D43>0,O42+1,O42) -> 0 | P43: =IF(H43>0,H43+I43,"") -> 1684.1074
C44: 5 JT(s) R3 Tubing Joint,7" 29# JFE LION HP2 13CR 95, BOX x PIN | H44: =H43-G44 -> 1679.0524 | I44: =I43+G44 -> 5.055 | O44: =IF(D44>0,O43+1,O43) -> 0 | P44: =IF(H44>0,H44+I44,"") -> 1684.1074
...

Sheet Tally
C2: Pre-Drilled LINER/Blanks | G2: Production Casing/Tubing | K2: WASH PIPE | M2: Total | N2: =C374 -> 446.747
B3: =O10 -> 7" | C3: =O16 -> L80 13CR / Vam Top | D3: UOM | G3: =O10 -> 7" | H3: =O12 -> Hp2 13CR 95 / JFE Lion | K3: 3-1/2" HYDRIL 511
A4: Jt # | B4: M'SURED | C4: ADJUSTED | D4: METER (m) | F4: Jt # | G4: M'SURED | H4: ADJUSTED | J4: Jt # | K4: M'SURED | L4: ADJUSTED | M4: Average | N4: =C376 -> 12.409639 | O4: =F376 -> 135.5 | P4: =#REF! -> #REF!
A5: BP1 | B5: 12.6 | C5: =B5-$O$17 -> 12.479 | D5: Blanks | F5: 1 | G5: 12.231027 | H5: =G5-$O$13 -> 12.108027 | I5: Upper Completion Well A1 | J5: 1 | K5: 8.72 | L5: =K5-$O$21 -> 8.65 | M5: Bundle A | S5: 43 | T5: 11.6
A6: BP2 | B6: 12.585 | C6: =B6-$O$17 -> 12.464 | F6: 2 | G6: 11.590978 | H6: =G6-$O$13 -> 11.467978 | J6: 2 | K6: 8.715 | L6: =K6-$O$21 -> 8.645 | N6: Well | O6: Jerun A-4 | S6: 42 | T6: 11.705
A7: BP3 | B7: 12.315 | C7: =B7-$O$17 -> 12.194 | F7: 3 | G7: 12.29808 | H7: =G7-$O$13 -> 12.17508 | J7: 3 | K7: 8.7 | L7: =K7-$O$21 -> 8.63 | S7: 41 | T7: 11.58
A8: BP4 | B8: 12.58 | C8: =B8-$O$17 -> 12.459 | F8: 4 | G8: 12.450472 | H8: =G8-$O$13 -> 12.327472 | J8: 4 | K8: 8.52 | L8: =K8-$O$21 -> 8.45 | N8: Rig | O8: GUNNLOD BORR | S8: 40 | T8: 11.71
A9: BP5 | B9: 12.52 | C9: =B9-$O$17 -> 12.399 | F9: 5 | G9: 12.267601 | H9: =G9-$O$13 -> 12.144601 | J9: 5 | K9: 9.56 | L9: =K9-$O$21 -> 9.49 | S9: 39 | T9: 11.705
A10: BP6 | B10: 12.575 | C10: =B10-$O$17 -> 12.454 | F10: 6 | G10: 12.221884 | H10: =G10-$O$13 -> 12.098884 | J10: 6 | K10: 9.63 | L10: =K10-$O$21 -> 9.56 | N10: Prod Cas | O10: 7" | S10: 38 | T10: 11.71
A11: BP7 | B11: 12.6 | C11: =B11-$O$17 -> 12.479 | F11: 7 | G11: 12.53886 | H11: =G11-$O$13 -> 12.41586 | J11: 7 | K11: 9.705 | L11: =K11-$O$21 -> 9.635 | N11: Weight | O11: 29 ppf | S11: 37 | T11: 11.71
A12: BP8 | B12: 12.593 | C12: =B12-$O$17 -> 12.472 | F12: 8 | G12: 12.224931 | H12: =G12-$O$13 -> 12.101931 | J12: 8 | K12: 9.69 | L12: =K12-$O$21 -> 9.62 | N12: Grade/ Thread | O12: Hp2 13CR 95 / JFE Lion | S12: 36 | T12: 11.275
A13: BP9 | B13: 12.103 | C13: =B13-$O$17 -> 11.982 | F13: 9 | G13: 12.359037 | H13: =G13-$O$13 -> 12.236037 | J13: 9 | K13: 9.71 | L13: =K13-$O$21 -> 9.64 | N13: Make Up Loss | O13: 0.123 | P13: meter | S13: 35 | T13: 11.71
A14: BP10 | B14: 12.07 | C14: =B14-$O$17 -> 11.949 | F14: 10 | G14: 12.694301 | H14: =G14-$O$13 -> 12.571301 | J14: 10 | K14: 9.605 | L14: =K14-$O$21 -> 9.535 | N14: Liner | O14: 7" | S14: 34 | T14: 11.715
A15: BP11 | B15: 12.54 | C15: =B15-$O$17 -> 12.419 | F15: 11 | G15: 12.08473 | H15: =G15-$O$13 -> 11.96173 | J15: 11 | K15: 9.7 | L15: =K15-$O$21 -> 9.63 | N15: Weight | O15: 26 ppf | S15: 33 | T15: 11.6
A16: BP12 | B16: 12.65 | C16: =B16-$O$17 -> 12.529 | F16: 12 | G16: 11.584883 | H16: =G16-$O$13 -> 11.461883 | J16: 12 | K16: 9.7 | L16: =K16-$O$21 -> 9.63 | N16: Grade/ Thread | O16: L80 13CR / Vam Top | S16: 32 | T16: 11.71
A17: BP13 | B17: 12.38 | C17: =B17-$O$17 -> 12.259 | F17: 13 | G17: 12.276745 | H17: =G17-$O$13 -> 12.153745 | J17: 13 | K17: 9.698 | L17: =K17-$O$21 -> 9.628 | N17: Make Up Loss | O17: 0.121 | P17: meter | S17: 31 | T17: 11.71
A18: BP14 | B18: 12.375 | C18: =B18-$O$17 -> 12.254 | F18: 14 | G18: 12.925937 | H18: =G18-$O$13 -> 12.802937 | J18: 14 | K18: 9.135 | L18: =K18-$O$21 -> 9.065 | N18: Wash Pipe | O18: 3-1/2" | S18: 30 | T18: 11.71
A19: BP15 | B19: 12.65 | C19: =B19-$O$17 -> 12.529 | F19: 15 | G19: 12.584578 | H19: =G19-$O$13 -> 12.461578 | J19: 15 | K19: 9.66 | L19: =K19-$O$21 -> 9.59 | N19: Weight | O19: 9.2 ppf | S19: 29 | T19: 11.71
A20: BP16 | B20: 12.7 | C20: =B20-$O$17 -> 12.579 | F20: 16 | G20: 12.66687 | H20: =G20-$O$13 -> 12.54387 | J20: 16 | K20: 9.69 | L20: =K20-$O$21 -> 9.62 | N20: Grade/ Thread | O20: L80 | S20: 28 | T20: 11.705
A21: BP17 | B21: 12.6 | C21: =B21-$O$17 -> 12.479 | F21: 17 | G21: 12.304176 | H21: =G21-$O$13 -> 12.181176 | J21: 17 | K21: 9.72 | L21: =K21-$O$21 -> 9.65 | N21: Make Up Loss | O21: 0.07 | P21: meter | S21: 27 | T21: 11.705
A22: BP18 | B22: 12.6 | C22: =B22-$O$17 -> 12.479 | F22: 18 | G22: 12.645535 | H22: =G22-$O$13 -> 12.522535 | J22: 18 | K22: 9.63 | L22: =K22-$O$21 -> 9.56 | O22: Landing Jt | S22: 26 | T22: 11.705
A23: L1 | B23: 12.59 | C23: =B23-$O$17 -> 12.469 | D23: Slotted | F23: 19 | G23: 12.234075 | H23: =G23-$O$13 -> 12.111075 | J23: 19 | K23: 9.603 | L23: =K23-$O$21 -> 9.533 | O23: Onboard | S23: 25 | T23: 11.695
A24: L2 | B24: 12.592 | C24: =B24-$O$17 -> 12.471 | F24: 20 | G24: 12.697348 | H24: =G24-$O$13 -> 12.574348 | J24: 20 | K24: 9.69 | L24: =K24-$O$21 -> 9.62 | O24: Back Up/Balance | S24: 24 | T24: 11.585
A25: L3 | B25: 12.075 | C25: =B25-$O$17 -> 11.954 | F25: 21 | G25: 12.505334 | H25: =G25-$O$13 -> 12.382334 | J25: 21 | K25: 9.7 | L25: =K25-$O$21 -> 9.63 | O25: Damaged | S25: 23 | T25: 11.71
A26: L4 | B26: 12.607 | C26: =B26-$O$17 -> 12.486 | F26: 22 | G26: 12.797927 | H26: =G26-$O$13 -> 12.674927 | J26: 22 | K26: 9.69 | L26: =K26-$O$21 -> 9.62 | S26: 22 | T26: 11.71
A27: L5 | B27: 12.587 | C27: =B27-$O$17 -> 12.466 | F27: 23 | G27: 12.764401 | H27: =G27-$O$13 -> 12.641401 | J27: 23 | K27: 9.7 | L27: =K27-$O$21 -> 9.63 | S27: 21 | T27: 11.71
A28: L6 | B28: 12.59 | C28: =B28-$O$17 -> 12.469 | F28: 24 | G28: 12.352941 | H28: =G28-$O$13 -> 12.229941 | J28: 24 | K28: 9.69 | L28: =K28-$O$21 -> 9.62 | M28: Bundle B | S28: 20 | T28: 11.71
A29: L7 | B29: 12.593 | C29: =B29-$O$17 -> 12.472 | F29: 25 | G29: 12.279793 | H29: =G29-$O$13 -> 12.156793 | J29: 25 | K29: 9.705 | L29: =K29-$O$21 -> 9.635 | S29: 19 | T29: 11.75
A30: L8 | B30: 12.585 | C30: =B30-$O$17 -> 12.464 | F30: 26 | G30: 12.188357 | H30: =G30-$O$13 -> 12.065357 | J30: 26 | K30: 9.69 | L30: =K30-$O$21 -> 9.62 | S30: 18 | T30: 11.71
A31: L9 | B31: 12.582 | C31: =B31-$O$17 -> 12.461 | F31: 27 | G31: 12.688205 | H31: =G31-$O$13 -> 12.565205 | J31: 27 | K31: 9.69 | L31: =K31-$O$21 -> 9.62 | S31: 17 | T31: 11.645
A32: L10 | B32: 12.587 | C32: =B32-$O$17 -> 12.466 | F32: 28 | G32: 12.359037 | H32: =G32-$O$13 -> 12.236037 | J32: 28 | K32: 9.705 | L32: =K32-$O$21 -> 9.635 | S32: 16 | T32: 11.715
A33: L11 | B33: 12.557 | C33: =B33-$O$17 -> 12.436 | F33: 29 | G33: 12.922889 | H33: =G33-$O$13 -> 12.799889 | J33: 29 | K33: 9.595 | L33: =K33-$O$21 -> 9.525 | S33: 15 | T33: 11.715
A34: L12 | B34: 12.6 | C34: =B34-$O$17 -> 12.479 | F34: 30 | G34: 12.419994 | H34: =G34-$O$13 -> 12.296994 | J34: 30 | K34: 9.695 | L34: =K34-$O$21 -> 9.625 | S34: 14 | T34: 11.71
A35: L13 | B35: 12.587 | C35: =B35-$O$17 -> 12.466 | F35: 31 | G35: 12.087778 | H35: =G35-$O$13 -> 11.964778 | J35: 31 | K35: 9.685 | L35: =K35-$O$21 -> 9.615 | S35: 13 | T35: 11.71
A36: L14 | B36: 12.593 | C36: =B36-$O$17 -> 12.472 | F36: 32 | G36: 12.432185 | H36: =G36-$O$13 -> 12.309185 | J36: 32 | K36: 9.705 | L36: =K36-$O$21 -> 9.635 | S36: 12 | T36: 11.71
A37: L15 | B37: 12.595 | C37: =B37-$O$17 -> 12.474 | F37: 33 | G37: 12.398659 | H37: =G37-$O$13 -> 12.275659 | J37: 33 | K37: 9.69 | L37: =K37-$O$21 -> 9.62 | S37: 11 | T37: 11.715
A38: L16 | B38: 12.583 | C38: =B38-$O$17 -> 12.462 | F38: 34 | G38: 11.749467 | H38: =G38-$O$13 -> 11.626467 | J38: 34 | K38: 9.695 | L38: =K38-$O$21 -> 9.625 | S38: 10 | T38: 11.71
A39: L17 | B39: 12.584 | C39: =B39-$O$17 -> 12.463 | F39: 35 | G39: 11.779945 | H39: =G39-$O$13 -> 11.656945 | J39: 35 | K39: 9.695 | L39: =K39-$O$21 -> 9.625 | S39: 9 | T39: 11.695
A40: L18 | B40: 12.58 | C40: =B40-$O$17 -> 12.459 | F40: 36 | G40: 12.627248 | H40: =G40-$O$13 -> 12.504248 | J40: 36 | K40: 9.69 | L40: =K40-$O$21 -> 9.62 | S40: 8 | T40: 11.71
F41: 37 | G41: 12.526669 | H41: =G41-$O$13 -> 12.403669 | J41: 37 | K41: 9.69 | L41: =K41-$O$21 -> 9.62 | S41: 7 | T41: 11.71
...

Sheet 7" JFE Pup Jts_UC
A1: =Tally!O6 -> Jerun A-4
A2: 7" 29# JFE Lion HP2 13CR 95
A4: MEASUREMENT END TO END
C5: RIH A1 | M5: M/UP LOSS: | P5: ft
C6: Space Out | O6: =Tally!O13 -> 0.123 | P6: m
C7: Damage
C8: RIH
A9: 20ft pup | E9: 15ft pup | I9: 12ft pup | M9: 10ft pup | Q9: 8ft pup
A10: No | B10: Measured | C10: Adjusted (m) | E10: No | F10: Measured | G10: Adjusted (m) | I10: No | J10: Measured | K10: Adjusted (m) | M10: No | N10: Measured | O10: Adjusted (m) | Q10: No | R10: Measured | S10: Adjusted (m)
I11: 12P1 | J11: 3.72 | K11: =J11-$O$6 -> 3.597 | L11: Meter | M11: 10P1 | N11: 3.109 | O11: =N11-$O$6 -> 2.986 | P11: Meter | Q11: 8P1 | R11: 2.502 | S11: =R11-$O$6 -> 2.379 | T11: Meter
I12: 12P2 | J12: 3.723 | K12: =J12-$O$6 -> 3.6 | L12: Meter | M12: 10P2 | N12: 3.036 | O12: =N12-$O$6 -> 2.913 | P12: Meter | Q12: 8P2 | R12: 2.502 | S12: =R12-$O$6 -> 2.379 | T12: Meter
I13: 12P3 | J13: 3.725 | K13: =J13-$O$6 -> 3.602 | L13: Meter | M13: 10P3 | N13: 3.115 | O13: =N13-$O$6 -> 2.992 | P13: Meter | Q13: 8P3 | R13: 2.49 | S13: =R13-$O$6 -> 2.367 | T13: Meter
I16: 12P10 | J16: =12.21/3.281 -> 3.7214264 | K16: =J16-$O$6 -> 3.5984264
I17: 12P11 | J17: =12.22/3.281 -> 3.7244742 | K17: =J17-$O$6 -> 3.6014742 | Q17: 8P10 | R17: =8.22/3.281 -> 2.5053337 | S17: =R17-$O$6 -> 2.3823337
I18: 12P12 | J18: =12.2/3.281 -> 3.7183785 | K18: =J18-$O$6 -> 3.5953785 | Q18: 8P11 | R18: =8.19/3.281 -> 2.4961902 | S18: =R18-$O$6 -> 2.3731902 | U18: *15ea P/jt LO for A-4
Q19: 8P12 | R19: =7.86/3.281 -> 2.3956111 | S19: =R19-$O$6 -> 2.2726111
A24: 6ft pup | E24: 4ft pup | I24: 3ft pup | M24: 2ft pup
A25: No | B25: Measured | C25: Adjusted (m) | E25: No | F25: Measured | G25: Adjusted (m) | I25: No | J25: Measured | K25: Adjusted (m) | M25: No | N25: Measured | O25: Adjusted (m)
A26: 6P1 | B26: 1.89 | C26: =B26-$O$6 -> 1.767 | D26: Meter | E26: 4P1 | F26: 1.259 | G26: =F26-$O$6 -> 1.136 | H26: Meter | I26: 3P1 | J26: 0.978 | K26: =J26-$O$6 -> 0.855 | L26: Meter
A27: 6P2 | B27: 1.896 | C27: =B27-$O$6 -> 1.773 | D27: Meter | E27: 4P2 | F27: 1.286 | G27: =F27-$O$6 -> 1.163 | H27: Meter | I27: 3P2 | J27: 0.978 | K27: =J27-$O$6 -> 0.855 | L27: Meter
A28: 6P3 | B28: 1.823 | C28: =B28-$O$6 -> 1.7 | D28: Meter | E28: 4P3 | F28: 1.286 | G28: =F28-$O$6 -> 1.163 | H28: Meter | I28: 3P3 | J28: 0.978 | K28: =J28-$O$6 -> 0.855 | L28: Meter | S28: =IF(R28>0, R28-0.0785,"")
S29: =IF(R29>0, R29-0.0785,"")
A32: 6P10 | B32: =6.22/3.281 -> 1.8957635 | C32: =B32-$O$6 -> 1.7727635 | E32: 4P10 | F32: =4.2/3.281 -> 1.2800975 | G32: =F32-$O$6 -> 1.1570975 | I32: 3P10 | J32: =3.22/3.281 -> 0.98140811 | K32: =J32-$O$6 -> 0.85840811
A33: 6P11 | B33: =5.99/3.281 -> 1.8256629 | C33: =B33-$O$6 -> 1.7026629 | E33: 4P11 | F33: =4.2/3.281 -> 1.2800975 | G33: =F33-$O$6 -> 1.1570975 | I33: 3P11 | J33: =3.22/3.281 -> 0.98140811 | K33: =J33-$O$6 -> 0.85840811
A34: 6P12 | B34: =6.21/3.281 -> 1.8927156 | C34: =B34-$O$6 -> 1.7697156 | E34: 4P12 | F34: =4.2/3.281 -> 1.2800975 | G34: =F34-$O$6 -> 1.1570975 | I34: 3P12 | J34: =3.21/3.281 -> 0.97836026 | K34: =J34-$O$6 -> 0.85536026
S37: =IF(R37>0, R37-0.0785,"")

Sheet 7" VT Pup Jts
A1: =Tally!O6 -> Jerun A-4
A2: 7" 26# VAM TOP 13CR L80
A4: MEASUREMENT END TO END
C5: RIH | M5: M/UP LOSS: | P5: ft
C6: Space Out | O6: =Tally!O17 -> 0.121 | P6: m
C7: Damage
A9: 20ft pup | E9: 15ft pup | I9: 12ft pup | M9: 10ft pup | Q9: 8ft pup
A10: No | B10: Measured | C10: Adjusted (m) | E10: No | F10: Measured | G10: Adjusted (m) | I10: No | J10: Measured | K10: Adjusted (m) | M10: No | N10: Measured | O10: Adjusted (m) | Q10: No | R10: Measured | S10: Adjusted (m)
I11: 12VT-1 | J11: 3.72 | K11: =J11-$O$6 -> 3.599 | M11: 10VT-1 | N11: 3.11 | O11: =N11-$O$6 -> 2.989 | Q11: 8VT-1 | R11: 2.505 | S11: =R11-$O$6 -> 2.384
I12: 12VT-2 | J12: 3.717 | K12: =J12-$O$6 -> 3.596 | M12: 10VT-2 | N12: 3.112 | O12: =N12-$O$6 -> 2.991 | Q12: 8VT-2 | R12: 2.508 | S12: =R12-$O$6 -> 2.387
I13: 12VT-3 | J13: 3.716 | K13: =J13-$O$6 -> 3.595 | M13: 10VT-3 | N13: 3.11 | O13: =N13-$O$6 -> 2.989
I14: 12VT-4 | J14: 3.72 | K14: =J14-$O$6 -> 3.599 | M14: 10VT-4 | N14: 3.11 | O14: =N14-$O$6 -> 2.989
I15: 12VT-5 | J15: 3.72 | K15: =J15-$O$6 -> 3.599 | M15: 10VT-5 | N15: 3.11 | O15: =N15-$O$6 -> 2.989
I16: 12VT-6 | J16: 3.718 | K16: =J16-$O$6 -> 3.597
I17: 12VT-7 | J17: 3.72 | K17: =J17-$O$6 -> 3.599
A24: 6ft pup | E24: 4ft pup | I24: 3ft pup | M24: 2ft pup
A25: No | B25: Measured | C25: Adjusted (m) | E25: No | F25: Measured | G25: Adjusted (m) | I25: No | J25: Measured | K25: Adjusted (m) | M25: No | N25: Measured | O25: Adjusted (m)
S28: =IF(R28>0, R28-0.0785,"")
S29: =IF(R29>0, R29-0.0785,"")
S37: =IF(R37>0, R37-0.0785,"")
